Workbook
Name LabChoices_1: 'Data'!$G$1:$G$4
Name LabChoices_2: 'Data'!$H$1:$H$4
Name LabChoices_3: 'Data'!$I$1:$I$4

Sheet Start Here
A1: Welcome to LAB02
A2: How should CloudFlow Analytics evaluate customer screening rules and capital investments under stochastic demand?
A4: 1. Your details
A5: First name | D5: Last name | G5: NYU NetID
A7: Your NetID is the username before @nyu.edu in your NYU email address. For example, jd1234@nyu.edu uses jd1234. Enter only the NetID here.
A8: Use your own details. For example only: first name Jane, last name Doe, NetID jd1234 gives LAB02_Jane_Doe_jd1234.xlsx. Keep hyphens in names; filenames omit spaces and unsupported punctuation.
A10: 2. Your submission filenames
A11: =IF(OR(LEN(TRIM(A6))=0,LEN(TRIM(D6))=0,LEN(TRIM(G6))=0),"Enter all three fields above to show your filenames.",IF(OR(ISNUMBER(SEARCH("@",G6)),ISNUMBER(SEARCH(" ",TRIM(G6))),AND(LEFT(UPPER(TRIM(G6)),1)="N",ISNUMBER(IFERROR(VALUE(MID(TRIM(G6),2,99)),"")))),"Enter only your NYU NetID, not your full email address or N-number.","Use File > Save As with the workbook name below. Save your other lab files with the matching names.")) -> Enter all three fields above to show your filenames.
A13: Excel workbook | C13: =IF(LEFT(A11,3)="Use","LAB02_"&SUBSTITUTE(SUBSTITUTE(SUBSTITUTE(SUBSTITUTE(SUBSTITUTE(SUBSTITUTE(SUBSTITUTE(SUBSTITUTE(SUBSTITUTE(SUBSTITUTE(TRIM(A6)," ",""),"/",""),"\",""),":",""),"*",""),"?",""),"""",""),"<",""),">",""),"|","")&"_"&SUBSTITUTE(SUBSTITUTE(SUBSTITUTE(SUBSTITUTE(SUBSTITUTE(SUBSTITUTE(SUBSTITUTE(SUBSTITUTE(SUBSTITUTE(SUBSTITUTE(TRIM(D6)," ",""),"/",""),"\",""),":",""),"*",""),"?",""),"""",""),"<",""),">",""),"|","")&"_"&LOWER(TRIM(G6))&".xlsx","")
A14: SPSS syntax | C14: =IF(LEFT(A11,3)="Use","LAB02_"&SUBSTITUTE(SUBSTITUTE(SUBSTITUTE(SUBSTITUTE(SUBSTITUTE(SUBSTITUTE(SUBSTITUTE(SUBSTITUTE(SUBSTITUTE(SUBSTITUTE(TRIM(A6)," ",""),"/",""),"\",""),":",""),"*",""),"?",""),"""",""),"<",""),">",""),"|","")&"_"&SUBSTITUTE(SUBSTITUTE(SUBSTITUTE(SUBSTITUTE(SUBSTITUTE(SUBSTITUTE(SUBSTITUTE(SUBSTITUTE(SUBSTITUTE(SUBSTITUTE(TRIM(D6)," ",""),"/",""),"\",""),":",""),"*",""),"?",""),"""",""),"<",""),">",""),"|","")&"_"&LOWER(TRIM(G6))&".sps","")
A15: SPSS output | C15: =IF(LEFT(A11,3)="Use","LAB02_"&SUBSTITUTE(SUBSTITUTE(SUBSTITUTE(SUBSTITUTE(SUBSTITUTE(SUBSTITUTE(SUBSTITUTE(SUBSTITUTE(SUBSTITUTE(SUBSTITUTE(TRIM(A6)," ",""),"/",""),"\",""),":",""),"*",""),"?",""),"""",""),"<",""),">",""),"|","")&"_"&SUBSTITUTE(SUBSTITUTE(SUBSTITUTE(SUBSTITUTE(SUBSTITUTE(SUBSTITUTE(SUBSTITUTE(SUBSTITUTE(SUBSTITUTE(SUBSTITUTE(TRIM(D6)," ",""),"/",""),"\",""),":",""),"*",""),"?",""),"""",""),"<",""),">",""),"|","")&"_"&LOWER(TRIM(G6))&".spv","")
A16: Memo (PDF) | C16: =IF(LEFT(A11,3)="Use","LAB02_"&SUBSTITUTE(SUBSTITUTE(SUBSTITUTE(SUBSTITUTE(SUBSTITUTE(SUBSTITUTE(SUBSTITUTE(SUBSTITUTE(SUBSTITUTE(SUBSTITUTE(TRIM(A6)," ",""),"/",""),"\",""),":",""),"*",""),"?",""),"""",""),"<",""),">",""),"|","")&"_"&SUBSTITUTE(SUBSTITUTE(SUBSTITUTE(SUBSTITUTE(SUBSTITUTE(SUBSTITUTE(SUBSTITUTE(SUBSTITUTE(SUBSTITUTE(SUBSTITUTE(TRIM(D6)," ",""),"/",""),"\",""),":",""),"*",""),"?",""),"""",""),"<",""),">",""),"|","")&"_"&LOWER(TRIM(G6))&".pdf","")
A17: Memo (Word) | C17: =IF(LEFT(A11,3)="Use","LAB02_"&SUBSTITUTE(SUBSTITUTE(SUBSTITUTE(SUBSTITUTE(SUBSTITUTE(SUBSTITUTE(SUBSTITUTE(SUBSTITUTE(SUBSTITUTE(SUBSTITUTE(TRIM(A6)," ",""),"/",""),"\",""),":",""),"*",""),"?",""),"""",""),"<",""),">",""),"|","")&"_"&SUBSTITUTE(SUBSTITUTE(SUBSTITUTE(SUBSTITUTE(SUBSTITUTE(SUBSTITUTE(SUBSTITUTE(SUBSTITUTE(SUBSTITUTE(SUBSTITUTE(TRIM(D6)," ",""),"/",""),"\",""),":",""),"*",""),"?",""),"""",""),"<",""),">",""),"|","")&"_"&LOWER(TRIM(G6))&".docx","")
A19: These are filenames, not extra required submissions. Follow the Submit section of the lab guide for which files to upload. Use either PDF or Word for the memo, as allowed there.
A21: 3. Learn, check and save
A22: Yellow cells are for your work. Read the study-help column beside response rows for relevant slides, concise toolkit pages and an optional question you can ask AI.
A23: AI help is optional and follows the lab’s permitted-use timing. Use it after class unless your lab guide explicitly permits it during class. Ask for a different practice example, check the explanation and disclose use or non-use.
A24: Use the guide for exact software steps. A matching number still needs an explanation. Save at each checkpoint. Your filenames update here, but this sheet does not rename or submit files.
A26: Open a Part
A27: IN-CLASS_Lab Part A: Cross-Tabulation and Conditional Churn Risk
A28: IN-CLASS_Lab Part B: Payoff Table and Decision Tree Valuation
A29: IN-CLASS_Lab Part C: Reproducible Stochastic Profit Simulation
A30: POST-CLASS_Part 1: Multi-Year Capital Investment Risk and Sensitivity

Sheet IN-CLASS_Lab Part A
A1: Part A · Do high-ticket accounts churn more? ⏱ 8 min · from slide 24 → back to slide 25
A2: What you're using · Section 1: A contingency table sorts every account by two categories at once. Reread: Slides 10–24; Concise Toolkit pp. 4–10; Full Toolkit pp. 4–21
A3: P(C | H) = P(C ∩ H) / P(H) = n(C ∩ H) / n(H) = B9 / D9 where C = account churned · H = account had high support tickets · n(·) = number of accounts
A4: ="Progress: "&COUNTIF(B30:B45,"✓ Checked")&" of 16 checked. Save after each ✓."
A5: Open IN-CLASS_Lab Part A!A7. Save workbook as LAB02_FirstName_LastName_NetID.xlsx. | I5: Study help (optional) Read the pages, then use the AI question if useful.
A7: 1 · Recorded source rows | C7: =IFERROR(IF(OR(ISBLANK(B7)),"Not started",IF(AND(ABS(B7-(1000))<=1e-09),"Result matches","Check the result")),"Formula error") | E7: Recorded source rows. Practice check: 1,000; use the cell's stated units. Do not count a manually selected partial range. | I7: B7: Section study support: Slides 11, 15, 17, 20. Concise Toolkit pp. 4-10 After-class AI question: Explain Descriptive Frequency Tables. Use a different example, then ask me one check question.
A8: HighTickets / Churn | B8: Yes | C8: No | D8: Row total
A9: Yes | E9: =IFERROR(IF(OR(ISBLANK(B9),ISBLANK(C9),ISBLANK(D9)),"Not started",IF(AND(ABS(B9-(96))<=1e-09,ABS(C9-(176))<=1e-09,ABS(D9-(272))<=1e-09),"Result matches","Check the result")),"Formula error") | G9: Yes. Practice check: 96; use the cell's stated units. Do not convert blank categories to No. | I9: B9:C9: Section study support: Slides 11, 15, 17, 20. Concise Toolkit pp. 4-10 After-class AI question: Explain Contingency Table Probabilities. Use a different example, then ask me one check question.
A10: No | E10: =IFERROR(IF(OR(ISBLANK(B10),ISBLANK(C10),ISBLANK(D10)),"Not started",IF(AND(ABS(B10-(24))<=1e-09,ABS(C10-(704))<=1e-09,ABS(D10-(728))<=1e-09),"Result matches","Check the result")),"Formula error") | G10: No. Practice check: 24; use the cell's stated units. Do not convert blank categories to No. | I10: B10:C10: Section study support: Slides 11, 15, 17, 20. Concise Toolkit pp. 4-10 After-class AI question: Explain Contingency Table Probabilities. Use a different example, then ask me one check question.
A11: 4 · Column total | E11: =IFERROR(IF(OR(ISBLANK(B11),ISBLANK(C11),ISBLANK(D11)),"Not started",IF(AND(ABS(B11-(120))<=1e-09,ABS(C11-(880))<=1e-09,ABS(D11-(1000))<=1e-09),"Result matches","Check the result")),"Formula error") | G11: Column total. Practice check: 120; use the cell's stated units. Do not assume the complete-pair count always equals the raw source-row count. | I11: B11:D11: Section study support: Slides 11, 15, 17, 20. Concise Toolkit pp. 4-10 After-class AI question: Explain Contingency Table Probabilities. Use a different example, then ask me one check question.
A13: 5 · Baseline churn probability | C13: =IFERROR(IF(OR(ISBLANK(B13)),"Not started",IF(AND(ABS(B13-(0.12))<=0.0015),"Result matches","Check the result")),"Formula error") | E13: Baseline churn probability. Practice check: 12.0%; use the cell's stated units. Do not divide by a ticket subgroup when calculating the baseline. | I13: B13: Section study support: Slides 11, 15, 17, 20. Concise Toolkit pp. 4-10 After-class AI question: Explain Contingency Table Probabilities. Use a different example, then ask me one check question.
A14: 6 · High-ticket marginal probability | C14: =IFERROR(IF(OR(ISBLANK(B14)),"Not started",IF(AND(ABS(B14-(0.272))<=0.0015),"Result matches","Check the result")),"Formula error") | E14: High-ticket marginal probability. Practice check: 27.2%; use the cell's stated units. Do not use all rows if Churn is missing. | I14: B14: Section study support: Slides 11, 15, 17, 20. Concise Toolkit pp. 4-10 After-class AI question: Explain Contingency Table Probabilities. Use a different example, then ask me one check question.
A15: 7 · Joint churn and high-ticket probability | C15: =IFERROR(IF(OR(ISBLANK(B15)),"Not started",IF(AND(ABS(B15-(0.096))<=0.0015),"Result matches","Check the result")),"Formula error") | E15: Joint churn and high-ticket probability. Practice check: 9.6%; use the cell's stated units. Do not divide by only the high-ticket subgroup for a joint probability. | I15: B15: Section study support: Slides 11, 15, 17, 20. Concise Toolkit pp. 4-10 After-class AI question: Explain Contingency Table Probabilities. Use a different example, then ask me one check question.
A16: 8 · Churn or high-ticket union | C16: =IFERROR(IF(OR(ISBLANK(B16)),"Not started",IF(AND(ABS(B16-(0.296))<=0.0015),"Result matches","Check the result")),"Formula error") | E16: Churn or high-ticket union. Practice check: 29.6%; use the cell's stated units. Do not add the margins without subtracting their overlap. | I16: B16: Section study support: Slides 11, 15, 17, 20. Concise Toolkit pp. 4-10 After-class AI question: Explain Contingency Table Probabilities. Use a different example, then ask me one check question.
A17: 9 · P(HighTickets | Churn) | C17: =IFERROR(IF(OR(ISBLANK(B17)),"Not started",IF(AND(ABS(B17-(0.8))<=0.0016),"Result matches","Check the result")),"Formula error") | E17: P(HighTickets | Churn). Practice check: 80.0%; use the cell's stated units. Do not reverse the condition when reporting the stakeholder risk. | I17: B17: Section study support: Slides 11, 15, 17, 20. Concise Toolkit pp. 4-10 After-class AI question: Explain Bayesian Updating. Use a different example, then ask me one check question.
A18: 10 · P(Churn | HighTickets) | C18: =IFERROR(IF(OR(ISBLANK(B18)),"Not started",IF(AND(ABS(B18-(0.352941176470588))<=0.0015),"Result matches","Check the result")),"Formula error") | E18: P(Churn | HighTickets). Practice check: 0.352941; use the cell's stated units. Do not use all source rows or the churned count as the denominator. | I18: B18: Section study support: Slides 11, 15, 17, 20. Concise Toolkit pp. 4-10 After-class AI question: Explain Bayesian Updating. Use a different example, then ask me one check question.
A20: Interpretation | I20: B20: Slides 20-21. Concise Toolkit pp. 4-10 After-class AI question: Explain Cross-Tabulation and Conditional Churn Risk. Use a different example, then ask me one check question.
A21: Reason | B21: [Replace with 2-3 sentences: state the numerator, denominator, comparison with baseline, and association-only limitation.] | I21: B21: Slides 20-21. Concise Toolkit pp. 4-10 After-class AI question: Explain Cross-Tabulation and Conditional Churn Risk. Use a different example, then ask me one check question.
A25: H1 evidence caption | B25: [Replace with 1-2 sentences: name H1 Conditional Churn Risk, identify the count and column percentage read, and state the Excel agreement check.] | I25: B25: Slides 20-21. Concise Toolkit pp. 4-10 After-class AI question: Explain Cross-Tabulation and Conditional Churn Risk. Use a different example, then ask me one check question.
A29: Check your work | B29: Status
A30: Source rows | B30: =IFERROR(IF('IN-CLASS_Lab Part A'!B7="","Not started",IF(ABS('IN-CLASS_Lab Part A'!B7-(1000))<=1e-09,"✓ Checked","Recheck method")),"Recheck formula")
A31: Yes yes | B31: =IFERROR(IF('IN-CLASS_Lab Part A'!B9="","Not started",IF(ABS('IN-CLASS_Lab Part A'!B9-(96))<=1e-09,"✓ Checked","Recheck method")),"Recheck formula")
A32: Yes no | B32: =IFERROR(IF('IN-CLASS_Lab Part A'!C9="","Not started",IF(ABS('IN-CLASS_Lab Part A'!C9-(176))<=1e-09,"✓ Checked","Recheck method")),"Recheck formula")
A33: No yes | B33: =IFERROR(IF('IN-CLASS_Lab Part A'!B10="","Not started",IF(ABS('IN-CLASS_Lab Part A'!B10-(24))<=1e-09,"✓ Checked","Recheck method")),"Recheck formula")
A34: No no | B34: =IFERROR(IF('IN-CLASS_Lab Part A'!C10="","Not started",IF(ABS('IN-CLASS_Lab Part A'!C10-(704))<=1e-09,"✓ Checked","Recheck method")),"Recheck formula")
A35: High yes total | B35: =IFERROR(IF('IN-CLASS_Lab Part A'!D9="","Not started",IF(ABS('IN-CLASS_Lab Part A'!D9-(272))<=1e-09,"✓ Checked","Recheck method")),"Recheck formula")
A36: High no total | B36: =IFERROR(IF('IN-CLASS_Lab Part A'!D10="","Not started",IF(ABS('IN-CLASS_Lab Part A'!D10-(728))<=1e-09,"✓ Checked","Recheck method")),"Recheck formula")
A37: Churn yes total | B37: =IFERROR(IF('IN-CLASS_Lab Part A'!B11="","Not started",IF(ABS('IN-CLASS_Lab Part A'!B11-(120))<=1e-09,"✓ Checked","Recheck method")),"Recheck formula")
A38: Churn no total | B38: =IFERROR(IF('IN-CLASS_Lab Part A'!C11="","Not started",IF(ABS('IN-CLASS_Lab Part A'!C11-(880))<=1e-09,"✓ Checked","Recheck method")),"Recheck formula")
A39: Complete pairs | B39: =IFERROR(IF('IN-CLASS_Lab Part A'!D11="","Not started",IF(ABS('IN-CLASS_Lab Part A'!D11-(1000))<=1e-09,"✓ Checked","Recheck method")),"Recheck formula")
A40: Baseline churn | B40: =IFERROR(IF('IN-CLASS_Lab Part A'!B13="","Not started",IF(ABS('IN-CLASS_Lab Part A'!B13-(0.12))<=0.0015,"✓ Checked","Recheck method")),"Recheck formula")
A41: High ticket margin | B41: =IFERROR(IF('IN-CLASS_Lab Part A'!B14="","Not started",IF(ABS('IN-CLASS_Lab Part A'!B14-(0.272))<=0.0015,"✓ Checked","Recheck method")),"Recheck formula")
A42: Joint probability | B42: =IFERROR(IF('IN-CLASS_Lab Part A'!B15="","Not started",IF(ABS('IN-CLASS_Lab Part A'!B15-(0.096))<=0.0015,"✓ Checked","Recheck method")),"Recheck formula")
A43: Union probability | B43: =IFERROR(IF('IN-CLASS_Lab Part A'!B16="","Not started",IF(ABS('IN-CLASS_Lab Part A'!B16-(0.296))<=0.0015,"✓ Checked","Recheck method")),"Recheck formula")
A44: High given churn | B44: =IFERROR(IF('IN-CLASS_Lab Part A'!B17="","Not started",IF(ABS('IN-CLASS_Lab Part A'!B17-(0.8))<=0.0016,"✓ Checked","Recheck method")),"Recheck formula")
A45: Churn given high | B45: =IFERROR(IF('IN-CLASS_Lab Part A'!B18="","Not started",IF(ABS('IN-CLASS_Lab Part A'!B18-(0.352941176470588))<=0.0015,"✓ Checked","Recheck method")),"Recheck formula")
A47: Formatting is already set. Enter your formula, then press Enter. To restore: select cell > Format Cells > Number or Custom.
A48: B7 | B48: Number, 0 decimals, records; unrelated example only: a stored count of 7 displays as 7 records. | Format code: 0
A49: B9 | B49: Number, 0 decimals, records; unrelated example only: a stored count of 7 displays as 7 records. | Format code: 0
A50: D9 | B50: Number, 0 decimals, records; unrelated example only: a stored count of 7 displays as 7 records. | Format code: 0
...

Sheet IN-CLASS_Lab Part B
A1: Part B · Large Hub or Modular Hub? ⏱ 10 min · from slide 42 → back to slide 43
A2: What you're using · Section 2: A decision separates what you control (the alternatives: Large Hub, Modular Hub) from what you don't (the states of nature: high, medium, low demand). Reread: Slides 25–42; Concise Toolkit pp. 11–18; Full Toolkit pp. 22–41
A3: Σᵢ₌₁³ P(sᵢ) = 1 EMV(dⱼ) = Σᵢ₌₁³ P(sᵢ) v(dⱼ, sᵢ) where dⱼ = alternative (hub) · sᵢ = demand state · v(dⱼ,sᵢ) = net payoff, million dollars
A4: ="Progress: "&COUNTIF(B28:B31,"✓ Checked")&" of 4 checked. Save after each ✓."
A5: Open IN-CLASS_Lab Part B!A7. Save workbook as LAB02_FirstName_LastName_NetID.xlsx. | I5: Study help (optional) Read the pages, then use the AI question if useful.
A7: 1 · Demand-state probability | I7: B7:D7: Section study support: Slides 27, 31, 33, 38. Concise Toolkit pp. 11-18 After-class AI question: Explain Payoff Table and Decision Tree Valuation. Use a different example, then ask me one check question.
A9: Alternative | B9: High demand | C9: Medium demand | D9: Low demand
A10: 2 · Large Hub | I10: B10:D10: Section study support: Slides 27, 31, 33, 38. Concise Toolkit pp. 11-18 After-class AI question: Explain Payoff Table and Decision Tree Valuation. Use a different example, then ask me one check question.
A11: 3 · Modular Hub | I11: B11:D11: Section study support: Slides 27, 31, 33, 38. Concise Toolkit pp. 11-18 After-class AI question: Explain Payoff Table and Decision Tree Valuation. Use a different example, then ask me one check question.
A14: 4 · Large Hub EMV | E14: =IFERROR(IF(OR(ISBLANK(D14)),"Not started",IF(AND(ABS(D14-(3.3))<=0.0066),"Result matches","Check the result")),"Formula error") | G14: Large Hub EMV. Practice check: 3.30; use the cell's stated units. Do not misalign a probability with the wrong demand-state payoff. | I14: D14: Slides 28-30. Concise Toolkit pp. 11-18 After-class AI question: Explain Expected Monetary Value. Use a different example, then ask me one check question.
A15: Modular Hub EMV | E15: =IFERROR(IF(OR(ISBLANK(D15)),"Not started",IF(AND(ABS(D15-(5.4))<=0.0108),"Result matches","Check the result")),"Formula error") | G15: Modular Hub EMV. Practice check: 5.4; use the cell's stated units. Do not describe EMV as the payoff that will occur in every state. | I15: D15: Slides 28-30. Concise Toolkit pp. 11-18 After-class AI question: Explain Expected Monetary Value. Use a different example, then ask me one check question.
A16: 5 · Rolled-back node value | E16: =IFERROR(IF(OR(ISBLANK(D16)),"Not started",IF(AND(ABS(D16-(5.4))<=0.0108),"Result matches","Check the result")),"Formula error") | G16: Rolled-back node value. Practice check: 5.40; use the cell's stated units. Do not use the largest single-state payoff instead of the branch EMVs. | I16: D16: Slides 38. Concise Toolkit pp. 11-18 After-class AI question: Explain Decision Tree Rollback. Use a different example, then ask me one check question.
A17: 6 · EMV premium | E17: =IFERROR(IF(OR(ISBLANK(D17)),"Not started",IF(AND(ABS(D17-(2.1))<=0.0042),"Result matches","Check the result")),"Formula error") | G17: EMV premium. Practice check: 2.10; use the cell's stated units. Do not present the premium as certain realized profit. | I17: D17: Slides 38. Concise Toolkit pp. 11-18 After-class AI question: Explain Decision Tree Rollback. Use a different example, then ask me one check question.
A18: Interpretation | I18: B18: Slides 27. Concise Toolkit pp. 11-18 After-class AI question: Explain Payoff Table and Decision Tree Valuation. Use a different example, then ask me one check question.
A19: Reason | B19: [Replace with 2-3 sentences: state the EMV criterion, selected branch, premium, and one risk-tolerance condition that could change the choice.] | I19: B19: Slides 27. Concise Toolkit pp. 11-18 After-class AI question: Explain Payoff Table and Decision Tree Valuation. Use a different example, then ask me one check question.
A23: H2 evidence caption | B23: [Replace with 1-2 sentences: name H2 Capacity EMV Audit, identify the values read, and state the Excel agreement check.] | I23: B23: Slides 27. Concise Toolkit pp. 11-18 After-class AI question: Explain Payoff Table and Decision Tree Valuation. Use a different example, then ask me one check question.
A27: Check your work | B27: Status
A28: Large emv | B28: =IFERROR(IF('IN-CLASS_Lab Part B'!D14="","Not started",IF(ABS('IN-CLASS_Lab Part B'!D14-(3.3))<=0.0066,"✓ Checked","Recheck method")),"Recheck formula")
A29: Modular emv | B29: =IFERROR(IF('IN-CLASS_Lab Part B'!D15="","Not started",IF(ABS('IN-CLASS_Lab Part B'!D15-(5.4))<=0.0108,"✓ Checked","Recheck method")),"Recheck formula")
A30: Rollback value | B30: =IFERROR(IF('IN-CLASS_Lab Part B'!D16="","Not started",IF(ABS('IN-CLASS_Lab Part B'!D16-(5.4))<=0.0108,"✓ Checked","Recheck method")),"Recheck formula")
A31: Emv premium | B31: =IFERROR(IF('IN-CLASS_Lab Part B'!D17="","Not started",IF(ABS('IN-CLASS_Lab Part B'!D17-(2.1))<=0.0042,"✓ Checked","Recheck method")),"Recheck formula")
A33: Formatting is already set. Enter your formula, then press Enter. To restore: select cell > Format Cells > Number or Custom.
A34: B7 | B34: Percentage, 1 decimal; unrelated example only: a stored fraction of 0.125 displays as 12.5%; enter a fraction, not a value multiplied by 100. | Format code: 0.0%
A35: C7 | B35: Percentage, 1 decimal; unrelated example only: a stored fraction of 0.125 displays as 12.5%; enter a fraction, not a value multiplied by 100. | Format code: 0.0%
A36: D7 | B36: Percentage, 1 decimal; unrelated example only: a stored fraction of 0.125 displays as 12.5%; enter a fraction, not a value multiplied by 100. | Format code: 0.0%
A37: B10 | B37: Number, 2 decimals, million dollars; unrelated example only: a stored value of 2.346 displays as 2.35 million dollars. | Format code: 0.00
A38: C10 | B38: Number, 2 decimals, million dollars; unrelated example only: a stored value of 2.346 displays as 2.35 million dollars. | Format code: 0.00
A39: D10 | B39: Number, 2 decimals, million dollars; unrelated example only: a stored value of 2.346 displays as 2.35 million dollars. | Format code: 0.00
A40: B11 | B40: Number, 2 decimals, million dollars; unrelated example only: a stored value of 2.346 displays as 2.35 million dollars. | Format code: 0.00
A41: C11 | B41: Number, 2 decimals, million dollars; unrelated example only: a stored value of 2.346 displays as 2.35 million dollars. | Format code: 0.00
A42: D11 | B42: Number, 2 decimals, million dollars; unrelated example only: a stored value of 2.346 displays as 2.35 million dollars. | Format code: 0.00
A43: D14 | B43: Number, 2 decimals, million dollars; unrelated example only: a stored value of 2.346 displays as 2.35 million dollars. | Format code: 0.00
A44: D15 | B44: Number, 2 decimals, million dollars; unrelated example only: a stored value of 2.346 displays as 2.35 million dollars. | Format code: 0.00
A45: D16 | B45: Number, 2 decimals, million dollars; unrelated example only: a stored value of 2.346 displays as 2.35 million dollars. | Format code: 0.00
A46: D17 | B46: Number, 2 decimals, million dollars; unrelated example only: a stored value of 2.346 displays as 2.35 million dollars. | Format code: 0.00
A48: ⚠ Most common mistake: Picking the Large Hub because it has the biggest single payoff ($12M). The EMV rule weighs every state by its probability, and the Large Hub's -$9M low-demand state pulls its EMV down.

Sheet IN-CLASS_Lab Part C
A1: Part C · Is profit at average demand too optimistic? ⏱ 15 min · from slide 65 → back to slide 66
A2: What you're using · Section 3: The flaw of averages: plugging average demand into a nonlinear model does not give average profit. Reread: Slides 44–65; Concise Toolkit pp. 19–25; Full Toolkit pp. 42–63
A3: Dₖ = μ + σ Φ⁻¹(uₖ) (μ = 1000, σ = 250) where D = demand · Q = capacity (1,000) · p = price ($100) · s = salvage ($15) · c = cost ($40) · uₖ = fixed probability for trial k
A4: ="Progress: "&COUNTIF(B1042:B1049,"✓ Checked")&" of 8 checked. Save after each ✓."
A5: Open IN-CLASS_Lab Part C!A7. Save workbook as LAB02_FirstName_LastName_NetID.xlsx. | I5: Study help (optional) Read the pages, then use the AI question if useful.
A7: Mean demand | B7: 1000
A8: Demand standard deviation | B8: 250
A9: Capacity | B9: 1000
A10: Selling price | B10: 100
A11: Salvage value | B11: 15
A12: Acquisition cost | B12: 40
A14: 1 · Profit at mean demand | C14: =IFERROR(IF(OR(ISBLANK(B14)),"Not started",IF(AND(ABS(B14-(60000))<=1e-09),"Result matches","Check the result")),"Formula error") | E14: Profit at mean demand. Practice check: $60,000; use the cell's stated units. Do not remove the capacity or salvage bounds. | I14: B14: Slides 46-48. Concise Toolkit pp. 19-25 After-class AI question: Explain The Flaw of Averages. Use a different example, then ask me one check question.
A16: 5 · Mean simulated profit | C16: =IFERROR(IF(OR(ISBLANK(B16)),"Not started",IF(AND(ABS(B16-(51319.7511149516))<=102.639502229903),"Result matches","Check the result")),"Formula error") | E16: Mean simulated profit. Practice check: $51,320; use the cell's stated units. Do not average the demand column or optional live-workbook outcomes. | I16: B16: Section study support: Slides 45, 52, 54, 61. Concise Toolkit pp. 19-25 After-class AI question: Explain Monte Carlo Simulation Engine. Use a different example, then ask me one check question.
A17: 6 · Sample standard deviation | C17: =IFERROR(IF(OR(ISBLANK(B17)),"Not started",IF(AND(ABS(B17-(12701.3953419276))<=25.4027906838553),"Result matches","Check the result")),"Formula error") | E17: Sample standard deviation. Practice check: $12,701; use the cell's stated units. Do not use STDEV.P when the requested denominator is n-1. | I17: B17: Section study support: Slides 45, 52, 54, 61. Concise Toolkit pp. 19-25 After-class AI question: Explain Monte Carlo Simulation Engine. Use a different example, then ask me one check question.
A18: 7 · 5th-percentile profit | C18: =IFERROR(IF(OR(ISBLANK(B18)),"Not started",IF(AND(ABS(B18-(25884.1055019807))<=51.7682110039614),"Result matches","Check the result")),"Formula error") | E18: 5th-percentile profit. Practice check: $25,884; use the cell's stated units. Do not apply Percentage format or a different percentile convention. | I18: B18: Section study support: Slides 45, 52, 54, 61. Concise Toolkit pp. 19-25 After-class AI question: Explain Monte Carlo Simulation Engine. Use a different example, then ask me one check question.
A19: 8 · Deterministic-minus-simulated gap | C19: =IFERROR(IF(OR(ISBLANK(B19)),"Not started",IF(AND(ABS(B19-(8680.24888504843))<=17.3604977700969),"Result matches","Check the result")),"Formula error") | E19: Deterministic-minus-simulated gap. Practice check: $8,680; use the cell's stated units. Do not assume the gap must be zero because mean demand is unchanged. | I19: B19: Slides 46-48. Concise Toolkit pp. 19-25 After-class AI question: Explain The Flaw of Averages. Use a different example, then ask me one check question.
A20: 9 · Numeric profit trials | C20: =IFERROR(IF(OR(ISBLANK(B20)),"Not started",IF(AND(ABS(B20-(1000))<=1e-09),"Result matches","Check the result")),"Formula error") | E20: Numeric profit trials. Practice check: 1,000; use the cell's stated units. Do not treat an error, blank, or optional live outcome as a completed reference trial. | I20: B20: Section study support: Slides 45, 52, 54, 61. Concise Toolkit pp. 19-25 After-class AI question: Explain Monte Carlo Simulation Engine. Use a different example, then ask me one check question.
A22: Interpretation | I22: B22: Slides 61. Concise Toolkit pp. 19-25 After-class AI question: Explain Reproducible Stochastic Profit Simulation. Use a different example, then ask me one check question.
A23: Reason | B23: [Replace with 2-3 sentences: compare deterministic profit with fixed-reference mean simulated profit, interpret the inclusive fifth percentile in dollars, and state one model limitation; do not use optional F9 outcomes as exact evidence.] | I23: B23: Slides 61. Concise Toolkit pp. 19-25 After-class AI question: Explain Reproducible Stochastic Profit Simulation. Use a different example, then ask me one check question.
A27: H3 evidence caption | B27: [Replace with 1-2 sentences: name H3 Reference Profit Summary; report its mean, sample SD, inclusive fifth percentile, and trial count; compare the SPSS results with Excel within the stated tolerance. Report any optional Python/R comparison separately, only if you actually ran and checked it.] | I27: B27: Slides 61. Concise Toolkit pp. 19-25 After-class AI question: Explain Reproducible Stochastic Profit Simulation. Use a different example, then ask me one check question.
D32: =IFERROR(IF(OR(ISBLANK(B32),ISBLANK(C32)),"Not started",IF(AND(ABS(B32-(653.820722423058))<=1.30764144484612,ABS(C32-(30574.76140596))<=61.1495228119199),"Result matches","Check the result")),"Formula error") | F32: None. Practice check: 653.821; use the cell's stated units. Do not replace u_001 with RAND in the graded workbook; F9 variation belongs only to LAB02_Live_Exploration.xlsx. | I32: A32:C32: Section study support: Slides 45, 52, 54, 61. Concise Toolkit pp. 19-25 After-class AI question: Explain Reproducible Stochastic Profit Simulation. Use a different example, then ask me one check question.
A1033: Downside-governance checkpoint | B1033: [Replace with 2-3 sentences: use fixed-reference results to identify one expected-performance metric, one downside or spread metric, and one risk-tolerance condition that could change a decision; treat F9 variation as optional live exploration only.] | I1033: B1033: Slides 61. Concise Toolkit pp. 19-25 After-class AI question: Explain Reproducible Stochastic Profit Simulation. Use a different example, then ask me one check question.
A1037: H4 evidence caption | B1037: [Replace with 1-2 sentences: name H4 Applied Downside Check, identify the fixed-reference shortfall numerator and numeric-trial denominator, and state what the in-class method demonstrates without selecting a take-home option.] | I1037: B1037: Slides 61. Concise Toolkit pp. 19-25 After-class AI question: Explain Reproducible Stochastic Profit Simulation. Use a different example, then ask me one check question.
A1041: Check your work | B1041: Status
A1042: Deterministic profit | B1042: =IFERROR(IF('IN-CLASS_Lab Part C'!B14="","Not started",IF(ABS('IN-CLASS_Lab Part C'!B14-(60000))<=1e-09,"✓ Checked","Recheck method")),"Recheck formula")
A1043: Mean profit | B1043: =IFERROR(IF('IN-CLASS_Lab Part C'!B16="","Not started",IF(ABS('IN-CLASS_Lab Part C'!B16-(51319.7511149516))<=102.639502229903,"✓ Checked","Recheck method")),"Recheck formula")
A1044: Standard deviation profit | B1044: =IFERROR(IF('IN-CLASS_Lab Part C'!B17="","Not started",IF(ABS('IN-CLASS_Lab Part C'!B17-(12701.3953419276))<=25.4027906838553,"✓ Checked","Recheck method")),"Recheck formula")
A1045: P05 profit | B1045: =IFERROR(IF('IN-CLASS_Lab Part C'!B18="","Not started",IF(ABS('IN-CLASS_Lab Part C'!B18-(25884.1055019807))<=51.7682110039614,"✓ Checked","Recheck method")),"Recheck formula")
A1046: Flaw gap | B1046: =IFERROR(IF('IN-CLASS_Lab Part C'!B19="","Not started",IF(ABS('IN-CLASS_Lab Part C'!B19-(8680.24888504843))<=17.3604977700969,"✓ Checked","Recheck method")),"Recheck formula")
A1047: Trial count | B1047: =IFERROR(IF('IN-CLASS_Lab Part C'!B20="","Not started",IF(ABS('IN-CLASS_Lab Part C'!B20-(1000))<=1e-09,"✓ Checked","Recheck method")),"Recheck formula")
A1048: First demand | B1048: =IFERROR(IF('IN-CLASS_Lab Part C'!B32="","Not started",IF(ABS('IN-CLASS_Lab Part C'!B32-(653.820722423058))<=1.30764144484612,"✓ Checked","Recheck method")),"Recheck formula")
A1049: First profit | B1049: =IFERROR(IF('IN-CLASS_Lab Part C'!C32="","Not started",IF(ABS('IN-CLASS_Lab Part C'!C32-(30574.76140596))<=61.1495228119199,"✓ Checked","Recheck method")),"Recheck formula")
A1051: Formatting is already set. Enter your formula, then press Enter. To restore: select cell > Format Cells > Number or Custom.
A1052: B7 | B1052: Number, 0 decimals, units; unrelated example only: a stored value of 7.26 displays as 7 units. | Format code: 0
A1053: B8 | B1053: Number, 0 decimals, units; unrelated example only: a stored value of 7.26 displays as 7 units. | Format code: 0
A1054: B9 | B1054: Number, 0 decimals, units; unrelated example only: a stored value of 7.26 displays as 7 units. | Format code: 0
A1055: B10 | B1055: Currency, 0 decimals, dollars per unit; unrelated example only: a stored value of 7.26 displays as 7 dollars. | Format code: $#,##0
A1056: B11 | B1056: Currency, 0 decimals, dollars per surplus unit; unrelated example only: a stored value of 7.26 displays as 7 dollars. | Format code: $#,##0
A1057: B12 | B1057: Currency, 0 decimals, dollars per capacity unit; unrelated example only: a stored value of 7.26 displays as 7 dollars. | Format code: $#,##0
A1058: B14 | B1058: Currency, 0 decimals, dollars; unrelated example only: a stored value of 7260.4 displays as 7260 dollars. | Format code: $#,##0
...

Sheet POST-CLASS_Part 1
A1: Take-home · Option A or Option B for three years? ⏱ 45 min · at home
A2: What you're using · Section 4: The take-home reuses the Part C method on a three-year capital decision, using the three-layer model from the session: assumptions, then a one-trial engine, then 1,000 trials. Reread: Slides 66–76; Concise Toolkit pp. 26–32; Full Toolkit pp. 64–83
A3: zₖ = Φ⁻¹(uₖ) CFⱼ,ₖ = μⱼ + σⱼ zₖ where j = option (A or B) · Iⱼ = initial investment · μⱼ, σⱼ = mean and SD of annual cash flow · r = 0.08
A4: ="Progress: "&COUNTIF(B1041:B1055,"✓ Checked")&" of 15 checked. Save after each ✓."
A5: Open POST-CLASS_Part 1!A7. Save the same LAB02_FirstName_LastName_NetID.xlsx workbook. | I5: Study help (optional) Read the pages, then use the AI question if useful.
A7: Discount rate | B7: 0.08
A8: Investment horizon | B8: 3
A9: Assumption | B9: Option A | C9: Option B
A10: Initial investment | B10: 1000000 | C10: 900000
A11: Mean annual cash flow | B11: 551000 | C11: 498600
A12: Annual cash-flow standard deviation | B12: 187300 | C12: 100200
A17: 5 · Mean NPV | D17: =IFERROR(IF(OR(ISBLANK(B17),ISBLANK(C17)),"Not started",IF(AND(ABS(B17-(418599.339132431))<=837.198678264862,ABS(C17-(384201.709447328))<=768.403418894655),"Result matches","Check the result")),"Formula error") | F17: Mean NPV. Use the completed Parts and the stated units. Do not average annual cash flow instead of completed NPV. | I17: B17:C17: Section study support: Slides 67, 72. Concise Toolkit pp. 26-32 After-class AI question: Explain Downside Risk and Shortfall Probability. Use a different example, then ask me one check question.
A18: 6 · Sample NPV standard deviation | D18: =IFERROR(IF(OR(ISBLANK(B18),ISBLANK(C18)),"Not started",IF(AND(ABS(B18-(494991.913928358))<=989.983827856716,ABS(C18-(264806.138684578))<=529.612277369156),"Result matches","Check the result")),"Formula error") | F18: Sample NPV standard deviation. Use the completed Parts and the stated units. Do not use standard deviation alone as the loss measure. | I18: B18:C18: Section study support: Slides 67, 72. Concise Toolkit pp. 26-32 After-class AI question: Explain Downside Risk and Shortfall Probability. Use a different example, then ask me one check question.
A19: 7 · 5th-percentile NPV | D19: =IFERROR(IF(OR(ISBLANK(B19),ISBLANK(C19)),"Not started",IF(AND(ABS(B19-(-354956.509684554))<=709.913019369109,ABS(C19-(-29627.9544686465))<=59.2559089372931),"Result matches","Check the result")),"Formula error") | F19: 5th-percentile NPV. Use the completed Parts and the stated units. Do not apply Percentage format to NPV. | I19: B19:C19: Section study support: Slides 67, 72. Concise Toolkit pp. 26-32 After-class AI question: Explain Downside Risk and Shortfall Probability. Use a different example, then ask me one check question.
A20: 8 · Loss probability | D20: =IFERROR(IF(OR(ISBLANK(B20),ISBLANK(C20)),"Not started",IF(AND(ABS(B20-(0.193))<=0.0015,ABS(C20-(0.073))<=0.0015),"Result matches","Check the result")),"Formula error") | F20: Loss probability. Use the completed Parts and the stated units. Do not include blanks in the denominator or multiply the fraction by 100. | I20: B20:C20: Section study support: Slides 67, 72. Concise Toolkit pp. 26-32 After-class AI question: Explain Downside Risk and Shortfall Probability. Use a different example, then ask me one check question.
A21: 9 · Numeric NPV trials | D21: =IFERROR(IF(OR(ISBLANK(B21),ISBLANK(C21)),"Not started",IF(AND(ABS(B21-(1000))<=1e-09,ABS(C21-(1000))<=1e-09),"Result matches","Check the result")),"Formula error") | F21: Numeric NPV trials. Use the completed Parts and the stated units. Do not assume a filled-looking cell is numeric. | I21: B21:C21: Section study support: Slides 67, 72. Concise Toolkit pp. 26-32 After-class AI question: Explain Downside Risk and Shortfall Probability. Use a different example, then ask me one check question.
A22: 10 · Absolute mean-NPV gap | C22: =IFERROR(IF(OR(ISBLANK(B22)),"Not started",IF(AND(ABS(B22-(34397.6296851034))<=68.7952593702067),"Result matches","Check the result")),"Formula error") | E22: Absolute mean-NPV gap. Use the completed Parts and the stated units. Use B17 and C17 to identify which option has the larger mean. | I22: B22: Section study support: Slides 67, 72. Concise Toolkit pp. 26-32 After-class AI question: Explain Downside Risk and Shortfall Probability. Use a different example, then ask me one check question.
A23: 11 · Loss-probability gap | C23: =IFERROR(IF(OR(ISBLANK(B23)),"Not started",IF(AND(ABS(B23-(0.12))<=0.0015),"Result matches","Check the result")),"Formula error") | E23: Loss-probability gap. Use the completed Parts and the stated units. Do not divide the difference by one option unless relative change is requested. | I23: B23: Section study support: Slides 67, 72. Concise Toolkit pp. 26-32 After-class AI question: Explain Downside Risk and Shortfall Probability. Use a different example, then ask me one check question.
A25: Executive recommendation | B25: [Replace with 1-2 short paragraphs: recommend an option, cite mean NPV and loss probability with denominators, state one limitation, and name a reversal condition.] | I25: B25: Slides 81. Concise Toolkit pp. 26-32 After-class AI question: Explain Multi-Year Capital Investment Risk and Sensitivity. Use a different example, then ask me one check question.
A30: Memo evidence map | B30: [Replace with one line per claim: identify the screening or capital claim, then point to the exact workbook cells or named SPSS output supporting it.] | I30: B30: Slides 81. Concise Toolkit pp. 26-32 After-class AI question: Explain Multi-Year Capital Investment Risk and Sensitivity. Use a different example, then ask me one check question.
A34: AI disclosure | B34: [Replace with either No AI used, or identify the tool, task, retained output, changes, tests or source checks, and remaining limitations.] | I34: B34: Slides 81. Concise Toolkit pp. 26-32 After-class AI question: Explain Multi-Year Capital Investment Risk and Sensitivity. Use a different example, then ask me one check question.
G38: =IFERROR(IF(OR(ISBLANK(D38),ISBLANK(E38),ISBLANK(F38)),"Not started",IF(AND(ABS(D38-(-1.38471711030777))<=0.00276943422061553,ABS(E38-(-248409.029936173))<=496.818059872347,ABS(F38-(27371.8184666859))<=54.7436369333719),"Result matches","Check the result")),"Formula error") | I38: A38:F38: Slides 78. Concise Toolkit pp. 26-32 After-class AI question: Explain Multi-Year Capital Investment Risk and Sensitivity. Use a different example, then ask me one check question.
A1040: Check your work | B1040: Status
A1041: Th option a mean npv | B1041: =IFERROR(IF('POST-CLASS_Part 1'!B17="","Not started",IF(ABS('POST-CLASS_Part 1'!B17-(418599.339132431))<=837.198678264862,"✓ Checked","Recheck method")),"Recheck formula")
A1042: Th option b mean npv | B1042: =IFERROR(IF('POST-CLASS_Part 1'!C17="","Not started",IF(ABS('POST-CLASS_Part 1'!C17-(384201.709447328))<=768.403418894655,"✓ Checked","Recheck method")),"Recheck formula")
A1043: Th option a standard deviation npv | B1043: =IFERROR(IF('POST-CLASS_Part 1'!B18="","Not started",IF(ABS('POST-CLASS_Part 1'!B18-(494991.913928358))<=989.983827856716,"✓ Checked","Recheck method")),"Recheck formula")
A1044: Th option b standard deviation npv | B1044: =IFERROR(IF('POST-CLASS_Part 1'!C18="","Not started",IF(ABS('POST-CLASS_Part 1'!C18-(264806.138684578))<=529.612277369156,"✓ Checked","Recheck method")),"Recheck formula")
A1045: Th option a p05 npv | B1045: =IFERROR(IF('POST-CLASS_Part 1'!B19="","Not started",IF(ABS('POST-CLASS_Part 1'!B19-(-354956.509684554))<=709.913019369109,"✓ Checked","Recheck method")),"Recheck formula")
A1046: Th option b p05 npv | B1046: =IFERROR(IF('POST-CLASS_Part 1'!C19="","Not started",IF(ABS('POST-CLASS_Part 1'!C19-(-29627.9544686465))<=59.2559089372931,"✓ Checked","Recheck method")),"Recheck formula")
A1047: Th option a loss probability | B1047: =IFERROR(IF('POST-CLASS_Part 1'!B20="","Not started",IF(ABS('POST-CLASS_Part 1'!B20-(0.193))<=0.0015,"✓ Checked","Recheck method")),"Recheck formula")
A1048: Th option b loss probability | B1048: =IFERROR(IF('POST-CLASS_Part 1'!C20="","Not started",IF(ABS('POST-CLASS_Part 1'!C20-(0.073))<=0.0015,"✓ Checked","Recheck method")),"Recheck formula")
A1049: Th option a trial count | B1049: =IFERROR(IF('POST-CLASS_Part 1'!B21="","Not started",IF(ABS('POST-CLASS_Part 1'!B21-(1000))<=1e-09,"✓ Checked","Recheck method")),"Recheck formula")
A1050: Th option b trial count | B1050: =IFERROR(IF('POST-CLASS_Part 1'!C21="","Not started",IF(ABS('POST-CLASS_Part 1'!C21-(1000))<=1e-09,"✓ Checked","Recheck method")),"Recheck formula")
A1051: Th mean npv gap | B1051: =IFERROR(IF('POST-CLASS_Part 1'!B22="","Not started",IF(ABS('POST-CLASS_Part 1'!B22-(34397.6296851034))<=68.7952593702067,"✓ Checked","Recheck method")),"Recheck formula")
A1052: Th loss probability gap | B1052: =IFERROR(IF('POST-CLASS_Part 1'!B23="","Not started",IF(ABS('POST-CLASS_Part 1'!B23-(0.12))<=0.0015,"✓ Checked","Recheck method")),"Recheck formula")
A1053: Th first z-score | B1053: =IFERROR(IF('POST-CLASS_Part 1'!D38="","Not started",IF(ABS('POST-CLASS_Part 1'!D38-(-1.38471711030777))<=0.00276943422061553,"✓ Checked","Recheck method")),"Recheck formula")
A1054: Th first option a npv | B1054: =IFERROR(IF('POST-CLASS_Part 1'!E38="","Not started",IF(ABS('POST-CLASS_Part 1'!E38-(-248409.029936173))<=496.818059872347,"✓ Checked","Recheck method")),"Recheck formula")
A1055: Th first option b npv | B1055: =IFERROR(IF('POST-CLASS_Part 1'!F38="","Not started",IF(ABS('POST-CLASS_Part 1'!F38-(27371.8184666859))<=54.7436369333719,"✓ Checked","Recheck method")),"Recheck formula")
A1057: Formatting is already set. Enter your formula, then press Enter. To restore: select cell > Format Cells > Number or Custom.
A1058: B7 | B1058: Percentage, 1 decimal; unrelated example only: a stored fraction of 0.125 displays as 12.5%; do not multiply by 100. | Format code: 0.0%
...

Sheet Data
A1: AccountID | B1: Churn | C1: HighTickets | E1: Shared data: cloudflow_churn_cohort.csv | G1: Eighty percent of high-ticket accounts churn because 80% of churners had high tickets. | H1: Select the Large Hub because the highest possible payoff determines the best decision. | I1: The 5th-percentile profit is the probability that profit is negative.
A2: CF0001 | B2: No | C2: No | E2: Excel: use the table on this sheet. SPSS: use the supplied .sps import. | G2: High-ticket activity proves that an automated intervention will prevent churn. | H2: Under a risk-neutral EMV criterion, select the Modular Hub, while recognizing that its EMV is not a guaranteed outcome. | I2: The deterministic profit at mean demand must equal the mean simulated profit because mean demand is 1,000 units.
A3: CF0002 | B3: No | C3: No | E3: Python/R: read the matching CSV with the types and missing rules below. | G3: High-ticket accounts have higher recorded churn risk than the cohort baseline, supporting screening priority but not a causal claim. | H3: The alternatives are equivalent because the demand-state probabilities sum to one. | I3: A larger sample standard deviation guarantees a larger expected profit.
A4: CF0003 | B4: No | C4: No | E4: AccountID | text | Recorded CloudFlow account identifier preserved with leading zeroes. | units: identifier | missing: blank [] | G4: The conditional churn rate uses all 1,000 source accounts as its denominator. | H4: The Modular Hub guarantees a payoff of 5.40 million dollars in each demand state. | I4: Capacity and salvage terms make profit nonlinear, so profit at mean demand can differ from mean simulated profit.
A5: CF0004 | B5: No | C5: No | E5: Churn | text | Recorded account outcome with allowed nonblank values Yes and No. | units: category | missing: blank []
A6: CF0005 | B6: No | C6: No | E6: HighTickets | text | Whether the account met the recorded high-ticket indicator, with allowed nonblank values Yes and No. | units: category | missing: blank []
A7: CF0006 | B7: No | C7: No
A8: CF0007 | B8: No | C8: Yes
A9: CF0008 | B9: No | C9: No
A10: CF0009 | B10: No | C10: No
A11: CF0010 | B11: No | C11: Yes
A12: CF0011 | B12: No | C12: No
A13: CF0012 | B13: Yes | C13: Yes
A14: CF0013 | B14: No | C14: Yes
A15: CF0014 | B15: No | C15: No
A16: CF0015 | B16: No | C16: Yes
A17: CF0016 | B17: No | C17: No
A18: CF0017 | B18: No | C18: No
... A1001: CF1000 | B1001: No | C1001: Yes

Sheet Data_Trials
A1: trial | B1: u_001 | D1: Shared data: reference_trials.csv
A2: 1 | B2: 0.083069493 | D2: Excel: use the table on this sheet. SPSS: use the supplied .sps import.
A3: 2 | B3: 0.52150204 | D3: Python/R: read the matching CSV with the types and missing rules below.
A4: 3 | B4: 0.99276412 | D4: trial | integer | Reference trial number | units: index | missing: blank []
A5: 4 | B5: 0.14258173 | D5: u_001 | number | Shared uniform input u_001 | units: probability | missing: blank []
A6: 5 | B6: 0.84821989
A7: 6 | B7: 0.96742898
A8: 7 | B8: 0.97180153
A9: 8 | B9: 0.90269993
A10: 9 | B10: 0.39698463
A11: 10 | B11: 0.4334664
A12: 11 | B12: 0.93606458
A13: 12 | B13: 0.2273416
A14: 13 | B14: 0.23315671
A15: 14 | B15: 0.53071204
A16: 15 | B16: 0.99069771
A17: 16 | B17: 0.050386709
... A1001: 1000 | B1001: 0.61233542
