Workbook
Name LabChoices_1: 'Data'!$J$1:$J$4
Name LabChoices_2: 'Data'!$K$1:$K$4
Name LabChoices_3: 'Data'!$L$1:$L$4

Sheet Start Here
A1: Welcome to LAB01
A2: How should Metro E-Commerce Logistics audit fulfillment data and establish distributional performance baselines?
A4: 1. Your details
A5: First name | D5: Last name | G5: NYU NetID
A7: Your NetID is the username before @nyu.edu in your NYU email address. For example, jd1234@nyu.edu uses jd1234. Enter only the NetID here.
A8: Use your own details. For example only: first name Jane, last name Doe, NetID jd1234 gives LAB01_Jane_Doe_jd1234.xlsx. Keep hyphens in names; filenames omit spaces and unsupported punctuation.
A10: 2. Your submission filenames
A11: =IF(OR(LEN(TRIM(A6))=0,LEN(TRIM(D6))=0,LEN(TRIM(G6))=0),"Enter all three fields above to show your filenames.",IF(OR(ISNUMBER(SEARCH("@",G6)),ISNUMBER(SEARCH(" ",TRIM(G6))),AND(LEFT(UPPER(TRIM(G6)),1)="N",ISNUMBER(IFERROR(VALUE(MID(TRIM(G6),2,99)),"")))),"Enter only your NYU NetID, not your full email address or N-number.","Use File > Save As with the workbook name below. Save your other lab files with the matching names."))
A13: Excel workbook | C13: =IF(LEFT(A11,3)="Use","LAB01_"&SUBSTITUTE(SUBSTITUTE(SUBSTITUTE(SUBSTITUTE(SUBSTITUTE(SUBSTITUTE(SUBSTITUTE(SUBSTITUTE(SUBSTITUTE(SUBSTITUTE(TRIM(A6)," ",""),"/",""),"\",""),":",""),"*",""),"?",""),"""",""),"<",""),">",""),"|","")&"_"&SUBSTITUTE(SUBSTITUTE(SUBSTITUTE(SUBSTITUTE(SUBSTITUTE(SUBSTITUTE(SUBSTITUTE(SUBSTITUTE(SUBSTITUTE(SUBSTITUTE(TRIM(D6)," ",""),"/",""),"\",""),":",""),"*",""),"?",""),"""",""),"<",""),">",""),"|","")&"_"&LOWER(TRIM(G6))&".xlsx","")
A14: SPSS syntax | C14: =IF(LEFT(A11,3)="Use","LAB01_"&SUBSTITUTE(SUBSTITUTE(SUBSTITUTE(SUBSTITUTE(SUBSTITUTE(SUBSTITUTE(SUBSTITUTE(SUBSTITUTE(SUBSTITUTE(SUBSTITUTE(TRIM(A6)," ",""),"/",""),"\",""),":",""),"*",""),"?",""),"""",""),"<",""),">",""),"|","")&"_"&SUBSTITUTE(SUBSTITUTE(SUBSTITUTE(SUBSTITUTE(SUBSTITUTE(SUBSTITUTE(SUBSTITUTE(SUBSTITUTE(SUBSTITUTE(SUBSTITUTE(TRIM(D6)," ",""),"/",""),"\",""),":",""),"*",""),"?",""),"""",""),"<",""),">",""),"|","")&"_"&LOWER(TRIM(G6))&".sps","")
A15: SPSS output | C15: =IF(LEFT(A11,3)="Use","LAB01_"&SUBSTITUTE(SUBSTITUTE(SUBSTITUTE(SUBSTITUTE(SUBSTITUTE(SUBSTITUTE(SUBSTITUTE(SUBSTITUTE(SUBSTITUTE(SUBSTITUTE(TRIM(A6)," ",""),"/",""),"\",""),":",""),"*",""),"?",""),"""",""),"<",""),">",""),"|","")&"_"&SUBSTITUTE(SUBSTITUTE(SUBSTITUTE(SUBSTITUTE(SUBSTITUTE(SUBSTITUTE(SUBSTITUTE(SUBSTITUTE(SUBSTITUTE(SUBSTITUTE(TRIM(D6)," ",""),"/",""),"\",""),":",""),"*",""),"?",""),"""",""),"<",""),">",""),"|","")&"_"&LOWER(TRIM(G6))&".spv","")
A16: Memo (PDF) | C16: =IF(LEFT(A11,3)="Use","LAB01_"&SUBSTITUTE(SUBSTITUTE(SUBSTITUTE(SUBSTITUTE(SUBSTITUTE(SUBSTITUTE(SUBSTITUTE(SUBSTITUTE(SUBSTITUTE(SUBSTITUTE(TRIM(A6)," ",""),"/",""),"\",""),":",""),"*",""),"?",""),"""",""),"<",""),">",""),"|","")&"_"&SUBSTITUTE(SUBSTITUTE(SUBSTITUTE(SUBSTITUTE(SUBSTITUTE(SUBSTITUTE(SUBSTITUTE(SUBSTITUTE(SUBSTITUTE(SUBSTITUTE(TRIM(D6)," ",""),"/",""),"\",""),":",""),"*",""),"?",""),"""",""),"<",""),">",""),"|","")&"_"&LOWER(TRIM(G6))&".pdf","")
A17: Memo (Word) | C17: =IF(LEFT(A11,3)="Use","LAB01_"&SUBSTITUTE(SUBSTITUTE(SUBSTITUTE(SUBSTITUTE(SUBSTITUTE(SUBSTITUTE(SUBSTITUTE(SUBSTITUTE(SUBSTITUTE(SUBSTITUTE(TRIM(A6)," ",""),"/",""),"\",""),":",""),"*",""),"?",""),"""",""),"<",""),">",""),"|","")&"_"&SUBSTITUTE(SUBSTITUTE(SUBSTITUTE(SUBSTITUTE(SUBSTITUTE(SUBSTITUTE(SUBSTITUTE(SUBSTITUTE(SUBSTITUTE(SUBSTITUTE(TRIM(D6)," ",""),"/",""),"\",""),":",""),"*",""),"?",""),"""",""),"<",""),">",""),"|","")&"_"&LOWER(TRIM(G6))&".docx","")
A19: These are filenames, not extra required submissions. Follow the Submit section of the lab guide for which files to upload. Use either PDF or Word for the memo, as allowed there.
A21: 3. Learn, check and save
A22: Yellow cells are for your work. Read the study-help column beside response rows for relevant slides, concise toolkit pages and an optional question you can ask AI.
A23: AI help is optional and follows the lab’s permitted-use timing. Use it after class unless your lab guide explicitly permits it during class. Ask for a different practice example, check the explanation and disclose use or non-use.
A24: Use the guide for exact software steps. A matching number still needs an explanation. Save at each checkpoint. Your filenames update here, but this sheet does not rename or submit files.
A26: Open a Part
A27: =HYPERLINK("#'IN-CLASS_Lab Part A'!A1","IN-CLASS_Lab Part A: Audit Measurement Scales and Sentinel Values")
A28: =HYPERLINK("#'IN-CLASS_Lab Part B'!A1","IN-CLASS_Lab Part B: Compute Measures of Center and Dispersion")
A29: =HYPERLINK("#'IN-CLASS_Lab Part C'!A1","IN-CLASS_Lab Part C: Calculate Tukey Outlier Fences and Boxplot Boundaries")
A30: =HYPERLINK("#'IN-CLASS_Lab Part D'!A1","IN-CLASS_Lab Part D: Build Stacked Comparative Grouped Summary")
A31: =HYPERLINK("#'POST-CLASS_Part 1'!A1","POST-CLASS_Part 1: Synthesize Distributional Evidence and SLA Guardrails")

Sheet IN-CLASS_Lab Part A
A1: Part A · Can we trust the order file? ⏱ 6 min · from slide 26 → back to slide 27
A2: What you're using · Section 1: Before you average anything, check two things: what each column measures, and which stored values are not measurements at all. Reread: Slides 10–26; Concise Toolkit pp. 4–8; Full Toolkit pp. 4–24
A3: n₋₁ = count(Ageᵢ = -1) = B7 n₉₉₉ = count(xᵢ = 999) = B8 where N = rows in the order file · xᵢ = recorded latency of order i, in minutes · count(·) = number of rows that meet the condition
A4: ="Progress: "&COUNTIF(B19:B20,"✓ Checked")&" of 2 checked. Save after each ✓."
A5: Open IN-CLASS_Lab Part A!A7. Save a recovery copy as LAB01_S03_Checkpoint_PartA.xlsx without replacing your personalized working file; reopen the personalized workbook at 'IN-CLASS_Lab Part B'!A7.
A7: 1 · Age sentinel records | C7: =IFERROR(IF(OR(ISBLANK(B7)),"Not started",IF(AND(ABS(B7-(42))<=1e-09),"Result matches","Check the result")),"Formula error") | E7: Age sentinel records. Practice check: 42 records. Do not replace -1 with zero or delete the source rows.
A8: 2 · Latency sentinel records | C8: =IFERROR(IF(OR(ISBLANK(B8)),"Not started",IF(AND(ABS(B8-(42))<=1e-09),"Result matches","Check the result")),"Formula error") | E8: Latency sentinel records. Practice check: 42 records. Do not treat 999 as an unusually long valid delivery.
A9: Admissible OrderTier statement
A10: Reason | B10: [Replace with 2-4 sentences: state your choice, cite the relevant statistical rule or evidence, explain why it fits, and state one limitation.]
A14: SPSS H1 evidence caption | B14: [Replace with 1-2 sentences: identify the Variable Information and relevant Frequency Tables you read, and describe the measurement-level and sentinel checks you made using your own output.]
A18: Check your work | B18: Status
A19: Part a.age sentinel count | B19: =IFERROR(IF('IN-CLASS_Lab Part A'!B7="","Not started",IF(ABS('IN-CLASS_Lab Part A'!B7-(42))<=1e-09,"✓ Checked","Recheck method")),"Recheck formula")
A20: Part a.latency sentinel count | B20: =IFERROR(IF('IN-CLASS_Lab Part A'!B8="","Not started",IF(ABS('IN-CLASS_Lab Part A'!B8-(42))<=1e-09,"✓ Checked","Recheck method")),"Recheck formula")
A22: Formatting is already set. Enter your formula, then press Enter. To restore: select cell > Format Cells > Number or Custom.
A23: B7 | B23: Number, 0 decimals, records; unrelated formatting example only: stored 7 displays as 7 records. This example is not an expected answer. | Format code: 0
A24: B8 | B24: Number, 0 decimals, records; unrelated formatting example only: stored 7 displays as 7 records. This example is not an expected answer. | Format code: 0
A26: ⚠ Most common mistake: Subtracting both sentinel counts from 10,000. Each code belongs to its own column. Latency results exclude only the 999 codes in Latency_Minutes; the -1 codes affect age, not latency.

Sheet IN-CLASS_Lab Part B
A1: Part B · What does a typical order look like? ⏱ 7 min · from slide 45 → back to slide 46
A2: What you're using · Section 2: Center and spread answer two different questions: where does a typical order sit, and how much do orders vary around it? Reread: Slides 27–45; Concise Toolkit pp. 9–13; Full Toolkit pp. 25–47
A3: x = 1 / nΣᵢ₌₁ⁿ xᵢ = B7 s = √Σᵢ₌₁ⁿ (xᵢ - x)²n-1 = B9 where xᵢ = valid latency of order i, in minutes · n = valid orders · Q₁, Q₃ = first and third quartiles
A4: ="Progress: "&COUNTIF(B22:B25,"✓ Checked")&" of 4 checked. Save after each ✓."
A5: Open IN-CLASS_Lab Part B!A7. Save a recovery copy as LAB01_S03_Checkpoint_PartB.xlsx without replacing your personalized working file; reopen the personalized workbook at 'IN-CLASS_Lab Part C'!A7.
A7: 1 · Mean latency | C7: =IFERROR(IF(OR(ISBLANK(B7)),"Not started",IF(AND(ABS(B7-(28.4))<=0.0568),"Result matches","Check the result")),"Formula error") | E7: Mean latency. Practice check: 28.4 minutes. Including 999 would pull the mean upward and change the denominator.
A8: 2 · Median latency | C8: =IFERROR(IF(OR(ISBLANK(B8)),"Not started",IF(AND(ABS(B8-(22))<=1e-09),"Result matches","Check the result")),"Formula error") | E8: Median latency. Practice check: 22.0 minutes. Do not describe the median as an arithmetic average.
A9: 3 · Sample standard deviation | C9: =IFERROR(IF(OR(ISBLANK(B9)),"Not started",IF(AND(ABS(B9-(13.5137672584411))<=0.0270275345168823),"Result matches","Check the result")),"Formula error") | E9: Sample standard deviation. Practice check: 13.5 minutes. Do not use STDEV.P when the accepted concept requires sample standard deviation.
A10: 4 · Interquartile range | C10: =IFERROR(IF(OR(ISBLANK(B10)),"Not started",IF(AND(ABS(B10-(12))<=1e-09),"Result matches","Check the result")),"Formula error") | E10: Interquartile range. Practice check: 12.0 minutes. Do not mix exclusive and inclusive quartile conventions.
A12: Interpretation
A13: Reason | B13: [Replace with 2-4 sentences: state your choice, cite the relevant statistical rule or evidence, explain why it fits, and state one limitation.]
A17: SPSS H2 evidence caption | B17: [Replace with 1-2 sentences: name the exact SPSS output, identify the statistic and population or filter you read, then state the cross-tool check you performed.]
A21: Check your work | B21: Status
A22: Part b.mean latency | B22: =IFERROR(IF('IN-CLASS_Lab Part B'!B7="","Not started",IF(ABS('IN-CLASS_Lab Part B'!B7-(28.4))<=0.0568,"✓ Checked","Recheck method")),"Recheck formula")
A23: Part b.median latency | B23: =IFERROR(IF('IN-CLASS_Lab Part B'!B8="","Not started",IF(ABS('IN-CLASS_Lab Part B'!B8-(22))<=1e-09,"✓ Checked","Recheck method")),"Recheck formula")
A24: Part b.sample standard deviation latency | B24: =IFERROR(IF('IN-CLASS_Lab Part B'!B9="","Not started",IF(ABS('IN-CLASS_Lab Part B'!B9-(13.5137672584411))<=0.0270275345168823,"✓ Checked","Recheck method")),"Recheck formula")
A25: Part b.iqr latency | B25: =IFERROR(IF('IN-CLASS_Lab Part B'!B10="","Not started",IF(ABS('IN-CLASS_Lab Part B'!B10-(12))<=1e-09,"✓ Checked","Recheck method")),"Recheck formula")
A27: Formatting is already set. Enter your formula, then press Enter. To restore: select cell > Format Cells > Number or Custom.
A28: B7 | B28: Number, 1 decimal, minutes; unrelated formatting example only: stored 7.26 displays as 7.3 minutes. This example is not an expected answer. | Format code: 0.0
A29: B8 | B29: Number, 1 decimal, minutes; unrelated formatting example only: stored 7.26 displays as 7.3 minutes. This example is not an expected answer. | Format code: 0.0
A30: B9 | B30: Number, 1 decimal, minutes; unrelated formatting example only: stored 7.26 displays as 7.3 minutes. This example is not an expected answer. | Format code: 0.0
A31: B10 | B31: Number, 1 decimal, minutes; unrelated formatting example only: stored 7.26 displays as 7.3 minutes. This example is not an expected answer. | Format code: 0.0
A33: ⚠ Most common mistake: Averaging the whole column. AVERAGE(Orders[Latency_Minutes]) treats the 42 codes of 999 as real 999-minute deliveries. Every formula on this sheet must keep the FILTER(...<>999...) rule.

Sheet IN-CLASS_Lab Part C
A1: Part C · Which orders are unusually slow? ⏱ 6 min · from slide 67 → back to slide 68 | J1: =IF(AND(ISNUMBER('Data'!$F$2),'Data'!$F$2<>999,'Data'!$F$2<>""),'Data'!$F$2,"") | L1: part_c_valid_latency_xy_boxplot: count | M1: =COUNT('IN-CLASS_Lab Part C'!$J$1:$J$10000) | N1: 0.8 | O1: =$M$2 | P1: 0.8 | Q1: =$M$3 | R1: 1 | S1: =$M$8 | T1: 1 | U1: =$M$4 | V1: 0.9 | W1: =$M$8 | X1: 0.9 | Y1: =$M$9 | Z1: 1 | AA1: =IF(ISNUMBER('IN-CLASS_Lab Part C'!$J$1),'IN-CLASS_Lab Part C'!$J$1,NA())
A2: What you're using · Section 3: A boxplot draws the middle half of the data as a box and marks unusual values with Tukey fences. Reread: Slides 47–67; Concise Toolkit pp. 14–18; Full Toolkit pp. 48–69 | J2: =IF(AND(ISNUMBER('Data'!$F$3),'Data'!$F$3<>999,'Data'!$F$3<>""),'Data'!$F$3,"") | L2: part_c_valid_latency_xy_boxplot: q1 | M2: =IF($M$1=0,NA(),_xlfn.QUARTILE.EXC('IN-CLASS_Lab Part C'!$J$1:$J$10000,1)) | N2: 1.2 | O2: =$M$2 | P2: 1.2 | Q2: =$M$3 | R2: 1 | S2: =$M$2 | T2: 1 | U2: =$M$9 | V2: 1.1 | W2: =$M$8 | X2: 1.1 | Y2: =$M$9 | Z2: 1 | AA2: =IF(ISNUMBER('IN-CLASS_Lab Part C'!$J$2),'IN-CLASS_Lab Part C'!$J$2,NA())
A3: Upper = Q₃ + 1.5 IQR = B7 Lower = Q₁ - 1.5 IQR = B8 where Q₁, Q₃ = exclusive quartiles of valid latency · IQR = Part B cell B10 · 1.5 = Tukey's multiplier · x₍ₙ₎ = largest valid value | J3: =IF(AND(ISNUMBER('Data'!$F$4),'Data'!$F$4<>999,'Data'!$F$4<>""),'Data'!$F$4,"") | L3: part_c_valid_latency_xy_boxplot: median | M3: =IF($M$1=0,NA(),MEDIAN('IN-CLASS_Lab Part C'!$J$1:$J$10000)) | N3: 1.2 | O3: =$M$4 | Z3: 1 | AA3: =IF(ISNUMBER('IN-CLASS_Lab Part C'!$J$3),'IN-CLASS_Lab Part C'!$J$3,NA())
A4: ="Progress: "&COUNTIF(B23:B27,"✓ Checked")&" of 5 checked. Save after each ✓." | J4: =IF(AND(ISNUMBER('Data'!$F$5),'Data'!$F$5<>999,'Data'!$F$5<>""),'Data'!$F$5,"") | L4: part_c_valid_latency_xy_boxplot: q3 | M4: =IF($M$1=0,NA(),_xlfn.QUARTILE.EXC('IN-CLASS_Lab Part C'!$J$1:$J$10000,3)) | N4: 0.8 | O4: =$M$4 | Z4: 1 | AA4: =IF(ISNUMBER('IN-CLASS_Lab Part C'!$J$4),'IN-CLASS_Lab Part C'!$J$4,NA())
A5: Open IN-CLASS_Lab Part C!A7. Save a recovery copy as LAB01_S03_Checkpoint_PartC.xlsx without replacing your personalized working file; reopen the personalized workbook at 'IN-CLASS_Lab Part D'!A7. | J5: =IF(AND(ISNUMBER('Data'!$F$6),'Data'!$F$6<>999,'Data'!$F$6<>""),'Data'!$F$6,"") | L5: part_c_valid_latency_xy_boxplot: iqr | M5: =$M$4-$M$2 | N5: 0.8 | O5: =$M$2 | Z5: 1 | AA5: =IF(ISNUMBER('IN-CLASS_Lab Part C'!$J$5),'IN-CLASS_Lab Part C'!$J$5,NA())
J6: =IF(AND(ISNUMBER('Data'!$F$7),'Data'!$F$7<>999,'Data'!$F$7<>""),'Data'!$F$7,"") | L6: part_c_valid_latency_xy_boxplot: lower_fence | M6: =$M$2-1.5*$M$5 | Z6: 1 | AA6: =IF(ISNUMBER('IN-CLASS_Lab Part C'!$J$6),'IN-CLASS_Lab Part C'!$J$6,NA())
A7: 1 · Upper Tukey fence | C7: =IFERROR(IF(OR(ISBLANK(B7)),"Not started",IF(AND(ABS(B7-(49))<=1e-09),"Result matches","Check the result")),"Formula error") | E7: Upper Tukey fence. Practice check: 49.0 minutes. Do not include the 999 sentinel when calculating Q3. | J7: =IF(AND(ISNUMBER('Data'!$F$8),'Data'!$F$8<>999,'Data'!$F$8<>""),'Data'!$F$8,"") | L7: part_c_valid_latency_xy_boxplot: upper_fence | M7: =$M$4+1.5*$M$5 | Z7: 1 | AA7: =IF(ISNUMBER('IN-CLASS_Lab Part C'!$J$7),'IN-CLASS_Lab Part C'!$J$7,NA())
A8: 2 · Lower Tukey fence | C8: =IFERROR(IF(OR(ISBLANK(B8)),"Not started",IF(AND(ABS(B8-(1))<=1e-09),"Result matches","Check the result")),"Formula error") | E8: Lower Tukey fence. Practice check: 1.0 minutes. Do not reverse Q1 and Q3 or add when calculating the lower fence. | J8: =IF(AND(ISNUMBER('Data'!$F$9),'Data'!$F$9<>999,'Data'!$F$9<>""),'Data'!$F$9,"") | L8: part_c_valid_latency_xy_boxplot: lower_whisker | M8: =IF($M$1=0,NA(),_xlfn.AGGREGATE(15,6,'IN-CLASS_Lab Part C'!$J$1:$J$10000/(ISNUMBER('IN-CLASS_Lab Part C'!$J$1:$J$10000)*('IN-CLASS_Lab Part C'!$J$1:$J$10000>=$M$6)*('IN-CLASS_Lab Part C'!$J$1:$J$10000<=$M$7)),1)) | Z8: 1 | AA8: =IF(ISNUMBER('IN-CLASS_Lab Part C'!$J$8),'IN-CLASS_Lab Part C'!$J$8,NA())
A9: 3 · Records above upper fence | C9: =IFERROR(IF(OR(ISBLANK(B9)),"Not started",IF(AND(ABS(B9-(829))<=1e-09),"Result matches","Check the result")),"Formula error") | E9: Records above upper fence. Practice check: 829 records. Build the greater-than criterion with ">"&B7 rather than the text ">B7". | J9: =IF(AND(ISNUMBER('Data'!$F$10),'Data'!$F$10<>999,'Data'!$F$10<>""),'Data'!$F$10,"") | L9: part_c_valid_latency_xy_boxplot: upper_whisker | M9: =IF($M$1=0,NA(),_xlfn.AGGREGATE(14,6,'IN-CLASS_Lab Part C'!$J$1:$J$10000/(ISNUMBER('IN-CLASS_Lab Part C'!$J$1:$J$10000)*('IN-CLASS_Lab Part C'!$J$1:$J$10000>=$M$6)*('IN-CLASS_Lab Part C'!$J$1:$J$10000<=$M$7)),1)) | Z9: 1 | AA9: =IF(ISNUMBER('IN-CLASS_Lab Part C'!$J$9),'IN-CLASS_Lab Part C'!$J$9,NA())
A10: 4 · Largest valid latency | C10: =IFERROR(IF(OR(ISBLANK(B10)),"Not started",IF(AND(ABS(B10-(124))<=1e-09),"Result matches","Check the result")),"Formula error") | E10: Largest valid latency. Practice check: 124.0 minutes. Without the filter, MAX would return the 999 sentinel. | J10: =IF(AND(ISNUMBER('Data'!$F$11),'Data'!$F$11<>999,'Data'!$F$11<>""),'Data'!$F$11,"") | Z10: 1 | AA10: =IF(ISNUMBER('IN-CLASS_Lab Part C'!$J$10),'IN-CLASS_Lab Part C'!$J$10,NA())
A11: 5 · Second-largest valid latency | C11: =IFERROR(IF(OR(ISBLANK(B11)),"Not started",IF(AND(ABS(B11-(124))<=1e-09),"Result matches","Check the result")),"Formula error") | E11: Second-largest valid latency. Practice check: 124.0 minutes. Using k=1 would repeat the maximum. | J11: =IF(AND(ISNUMBER('Data'!$F$12),'Data'!$F$12<>999,'Data'!$F$12<>""),'Data'!$F$12,"") | Z11: 1 | AA11: =IF(ISNUMBER('IN-CLASS_Lab Part C'!$J$11),'IN-CLASS_Lab Part C'!$J$11,NA())
J12: =IF(AND(ISNUMBER('Data'!$F$13),'Data'!$F$13<>999,'Data'!$F$13<>""),'Data'!$F$13,"") | Z12: 1 | AA12: =IF(ISNUMBER('IN-CLASS_Lab Part C'!$J$12),'IN-CLASS_Lab Part C'!$J$12,NA())
A13: Fence interpretation | J13: =IF(AND(ISNUMBER('Data'!$F$14),'Data'!$F$14<>999,'Data'!$F$14<>""),'Data'!$F$14,"") | Z13: 1 | AA13: =IF(ISNUMBER('IN-CLASS_Lab Part C'!$J$13),'IN-CLASS_Lab Part C'!$J$13,NA())
A14: Reason and chart reading | B14: [Replace with 2-4 sentences: describe the visible pattern, cite the relevant measure and units, explain what it means, and state what the chart cannot establish.] | J14: =IF(AND(ISNUMBER('Data'!$F$15),'Data'!$F$15<>999,'Data'!$F$15<>""),'Data'!$F$15,"") | Z14: 1 | AA14: =IF(ISNUMBER('IN-CLASS_Lab Part C'!$J$14),'IN-CLASS_Lab Part C'!$J$14,NA())
J15: =IF(AND(ISNUMBER('Data'!$F$16),'Data'!$F$16<>999,'Data'!$F$16<>""),'Data'!$F$16,"") | Z15: 1 | AA15: =IF(ISNUMBER('IN-CLASS_Lab Part C'!$J$15),'IN-CLASS_Lab Part C'!$J$15,NA())
J16: =IF(AND(ISNUMBER('Data'!$F$17),'Data'!$F$17<>999,'Data'!$F$17<>""),'Data'!$F$17,"") | Z16: 1 | AA16: =IF(ISNUMBER('IN-CLASS_Lab Part C'!$J$16),'IN-CLASS_Lab Part C'!$J$16,NA())
J17: =IF(AND(ISNUMBER('Data'!$F$18),'Data'!$F$18<>999,'Data'!$F$18<>""),'Data'!$F$18,"") | Z17: 1 | AA17: =IF(ISNUMBER('IN-CLASS_Lab Part C'!$J$17),'IN-CLASS_Lab Part C'!$J$17,NA())
A18: SPSS H3 evidence caption | B18: [Replace with 1-2 sentences: name the exact SPSS output, identify the statistic and population or filter you read, then state the cross-tool check you performed.] | J18: =IF(AND(ISNUMBER('Data'!$F$19),'Data'!$F$19<>999,'Data'!$F$19<>""),'Data'!$F$19,"") | Z18: 1 | AA18: =IF(ISNUMBER('IN-CLASS_Lab Part C'!$J$18),'IN-CLASS_Lab Part C'!$J$18,NA())
J19: =IF(AND(ISNUMBER('Data'!$F$20),'Data'!$F$20<>999,'Data'!$F$20<>""),'Data'!$F$20,"") | Z19: 1 | AA19: =IF(ISNUMBER('IN-CLASS_Lab Part C'!$J$19),'IN-CLASS_Lab Part C'!$J$19,NA())
J20: =IF(AND(ISNUMBER('Data'!$F$21),'Data'!$F$21<>999,'Data'!$F$21<>""),'Data'!$F$21,"") | Z20: 1 | AA20: =IF(ISNUMBER('IN-CLASS_Lab Part C'!$J$20),'IN-CLASS_Lab Part C'!$J$20,NA())
J21: =IF(AND(ISNUMBER('Data'!$F$22),'Data'!$F$22<>999,'Data'!$F$22<>""),'Data'!$F$22,"") | Z21: 1 | AA21: =IF(ISNUMBER('IN-CLASS_Lab Part C'!$J$21),'IN-CLASS_Lab Part C'!$J$21,NA())
A22: Check your work | B22: Status | J22: =IF(AND(ISNUMBER('Data'!$F$23),'Data'!$F$23<>999,'Data'!$F$23<>""),'Data'!$F$23,"") | Z22: 1 | AA22: =IF(ISNUMBER('IN-CLASS_Lab Part C'!$J$22),'IN-CLASS_Lab Part C'!$J$22,NA())
A23: Part c.upper fence | B23: =IFERROR(IF('IN-CLASS_Lab Part C'!B7="","Not started",IF(ABS('IN-CLASS_Lab Part C'!B7-(49))<=1e-09,"✓ Checked","Recheck method")),"Recheck formula") | J23: =IF(AND(ISNUMBER('Data'!$F$24),'Data'!$F$24<>999,'Data'!$F$24<>""),'Data'!$F$24,"") | Z23: 1 | AA23: =IF(ISNUMBER('IN-CLASS_Lab Part C'!$J$23),'IN-CLASS_Lab Part C'!$J$23,NA())
A24: Part c.lower fence | B24: =IFERROR(IF('IN-CLASS_Lab Part C'!B8="","Not started",IF(ABS('IN-CLASS_Lab Part C'!B8-(1))<=1e-09,"✓ Checked","Recheck method")),"Recheck formula") | J24: =IF(AND(ISNUMBER('Data'!$F$25),'Data'!$F$25<>999,'Data'!$F$25<>""),'Data'!$F$25,"") | Z24: 1 | AA24: =IF(ISNUMBER('IN-CLASS_Lab Part C'!$J$24),'IN-CLASS_Lab Part C'!$J$24,NA())
A25: Part c.upper flag count | B25: =IFERROR(IF('IN-CLASS_Lab Part C'!B9="","Not started",IF(ABS('IN-CLASS_Lab Part C'!B9-(829))<=1e-09,"✓ Checked","Recheck method")),"Recheck formula") | J25: =IF(AND(ISNUMBER('Data'!$F$26),'Data'!$F$26<>999,'Data'!$F$26<>""),'Data'!$F$26,"") | Z25: 1 | AA25: =IF(ISNUMBER('IN-CLASS_Lab Part C'!$J$25),'IN-CLASS_Lab Part C'!$J$25,NA())
A26: Part c.maximum valid latency | B26: =IFERROR(IF('IN-CLASS_Lab Part C'!B10="","Not started",IF(ABS('IN-CLASS_Lab Part C'!B10-(124))<=1e-09,"✓ Checked","Recheck method")),"Recheck formula") | J26: =IF(AND(ISNUMBER('Data'!$F$27),'Data'!$F$27<>999,'Data'!$F$27<>""),'Data'!$F$27,"") | Z26: 1 | AA26: =IF(ISNUMBER('IN-CLASS_Lab Part C'!$J$26),'IN-CLASS_Lab Part C'!$J$26,NA())
A27: Part c.second largest valid latency | B27: =IFERROR(IF('IN-CLASS_Lab Part C'!B11="","Not started",IF(ABS('IN-CLASS_Lab Part C'!B11-(124))<=1e-09,"✓ Checked","Recheck method")),"Recheck formula") | J27: =IF(AND(ISNUMBER('Data'!$F$28),'Data'!$F$28<>999,'Data'!$F$28<>""),'Data'!$F$28,"") | Z27: 1 | AA27: =IF(ISNUMBER('IN-CLASS_Lab Part C'!$J$27),'IN-CLASS_Lab Part C'!$J$27,NA())
J28: =IF(AND(ISNUMBER('Data'!$F$29),'Data'!$F$29<>999,'Data'!$F$29<>""),'Data'!$F$29,"") | Z28: 1 | AA28: =IF(ISNUMBER('IN-CLASS_Lab Part C'!$J$28),'IN-CLASS_Lab Part C'!$J$28,NA())
A29: Formatting is already set. Enter your formula, then press Enter. To restore: select cell > Format Cells > Number or Custom. | J29: =IF(AND(ISNUMBER('Data'!$F$30),'Data'!$F$30<>999,'Data'!$F$30<>""),'Data'!$F$30,"") | Z29: 1 | AA29: =IF(ISNUMBER('IN-CLASS_Lab Part C'!$J$29),'IN-CLASS_Lab Part C'!$J$29,NA())
A30: B7 | B30: Number, 1 decimal, minutes; unrelated formatting example only: stored 7.26 displays as 7.3 minutes. This example is not an expected answer. | Format code: 0.0 | J30: =IF(AND(ISNUMBER('Data'!$F$31),'Data'!$F$31<>999,'Data'!$F$31<>""),'Data'!$F$31,"") | Z30: 1 | AA30: =IF(ISNUMBER('IN-CLASS_Lab Part C'!$J$30),'IN-CLASS_Lab Part C'!$J$30,NA())
A31: B8 | B31: Number, 1 decimal, minutes; unrelated formatting example only: stored 7.26 displays as 7.3 minutes. This example is not an expected answer. | Format code: 0.0 | J31: =IF(AND(ISNUMBER('Data'!$F$32),'Data'!$F$32<>999,'Data'!$F$32<>""),'Data'!$F$32,"") | Z31: 1 | AA31: =IF(ISNUMBER('IN-CLASS_Lab Part C'!$J$31),'IN-CLASS_Lab Part C'!$J$31,NA())
A32: B9 | B32: Number, 0 decimals, records; unrelated formatting example only: stored 7 displays as 7 records. This example is not an expected answer. | Format code: 0 | J32: =IF(AND(ISNUMBER('Data'!$F$33),'Data'!$F$33<>999,'Data'!$F$33<>""),'Data'!$F$33,"") | Z32: 1 | AA32: =IF(ISNUMBER('IN-CLASS_Lab Part C'!$J$32),'IN-CLASS_Lab Part C'!$J$32,NA())
A33: B10 | B33: Number, 1 decimal, minutes; unrelated formatting example only: stored 7.26 displays as 7.3 minutes. This example is not an expected answer. | Format code: 0.0 | J33: =IF(AND(ISNUMBER('Data'!$F$34),'Data'!$F$34<>999,'Data'!$F$34<>""),'Data'!$F$34,"") | Z33: 1 | AA33: =IF(ISNUMBER('IN-CLASS_Lab Part C'!$J$33),'IN-CLASS_Lab Part C'!$J$33,NA())
A34: B11 | B34: Number, 1 decimal, minutes; unrelated formatting example only: stored 7.26 displays as 7.3 minutes. This example is not an expected answer. | Format code: 0.0 | J34: =IF(AND(ISNUMBER('Data'!$F$35),'Data'!$F$35<>999,'Data'!$F$35<>""),'Data'!$F$35,"") | Z34: 1 | AA34: =IF(ISNUMBER('IN-CLASS_Lab Part C'!$J$34),'IN-CLASS_Lab Part C'!$J$34,NA())
J35: =IF(AND(ISNUMBER('Data'!$F$36),'Data'!$F$36<>999,'Data'!$F$36<>""),'Data'!$F$36,"") | Z35: 1 | AA35: =IF(ISNUMBER('IN-CLASS_Lab Part C'!$J$35),'IN-CLASS_Lab Part C'!$J$35,NA())
J36: =IF(AND(ISNUMBER('Data'!$F$37),'Data'!$F$37<>999,'Data'!$F$37<>""),'Data'!$F$37,"") | Z36: 1 | AA36: =IF(ISNUMBER('IN-CLASS_Lab Part C'!$J$36),'IN-CLASS_Lab Part C'!$J$36,NA())
J37: =IF(AND(ISNUMBER('Data'!$F$38),'Data'!$F$38<>999,'Data'!$F$38<>""),'Data'!$F$38,"") | Z37: 1 | AA37: =IF(ISNUMBER('IN-CLASS_Lab Part C'!$J$37),'IN-CLASS_Lab Part C'!$J$37,NA())
J38: =IF(AND(ISNUMBER('Data'!$F$39),'Data'!$F$39<>999,'Data'!$F$39<>""),'Data'!$F$39,"") | Z38: 1 | AA38: =IF(ISNUMBER('IN-CLASS_Lab Part C'!$J$38),'IN-CLASS_Lab Part C'!$J$38,NA())
J39: =IF(AND(ISNUMBER('Data'!$F$40),'Data'!$F$40<>999,'Data'!$F$40<>""),'Data'!$F$40,"") | Z39: 1 | AA39: =IF(ISNUMBER('IN-CLASS_Lab Part C'!$J$39),'IN-CLASS_Lab Part C'!$J$39,NA())
J40: =IF(AND(ISNUMBER('Data'!$F$41),'Data'!$F$41<>999,'Data'!$F$41<>""),'Data'!$F$41,"") | Z40: 1 | AA40: =IF(ISNUMBER('IN-CLASS_Lab Part C'!$J$40),'IN-CLASS_Lab Part C'!$J$40,NA())
...

Sheet IN-CLASS_Lab Part D
A1: Part D · Is Hub C really different? ⏱ 7 min · from slide 86 → back to slide 90
A2: What you're using · Section 4: To compare groups fairly, keep the data stacked (one row per order, one column for the group) and apply the same rules to every group. Reread: Slides 68–86; Concise Toolkit pp. 19–23; Full Toolkit pp. 70–94
A3: ng = B7:B9 xg = C7:C9 IQRg = Q_(3,g) - Q_(1,g) = F7:F9 where g = hub (A, B or C) · ng = valid orders in hub g · xg = hub median · Q_(1,g), Q_(3,g) = hub quartiles
A4: ="Progress: "&COUNTIF(B22:B41,"✓ Checked")&" of 20 checked. Save after each ✓."
A5: Open IN-CLASS_Lab Part D!A7. Save a recovery copy as LAB01_S03_InClass_Complete.xlsx without replacing the personalized workbook; resume take-home at 'IN-CLASS_Lab Part D'!B12. After B17:H18, continue at 'POST-CLASS_Part 1'!A7.
A6: Hub | B6: Valid count | C6: Median | D6: Q1 | E6: Q3 | F6: IQR
A7: Hub A | G7: =IFERROR(IF(OR(ISBLANK(B7),ISBLANK(C7),ISBLANK(D7),ISBLANK(E7),ISBLANK(F7)),"Not started",IF(AND(ABS(B7-(3319))<=1e-09,ABS(C7-(22))<=1e-09,ABS(D7-(19))<=1e-09,ABS(E7-(26))<=1e-09,ABS(F7-(7))<=1e-09),"Result matches","Check the result")),"Formula error")
A8: Hub B | G8: =IFERROR(IF(OR(ISBLANK(B8),ISBLANK(C8),ISBLANK(D8),ISBLANK(E8),ISBLANK(F8)),"Not started",IF(AND(ABS(B8-(3319))<=1e-09,ABS(C8-(22))<=1e-09,ABS(D8-(19))<=1e-09,ABS(E8-(26))<=1e-09,ABS(F8-(7))<=1e-09),"Result matches","Check the result")),"Formula error")
A9: Hub C | G9: =IFERROR(IF(OR(ISBLANK(B9),ISBLANK(C9),ISBLANK(D9),ISBLANK(E9),ISBLANK(F9)),"Not started",IF(AND(ABS(B9-(3320))<=1e-09,ABS(C9-(22))<=1e-09,ABS(D9-(14))<=1e-09,ABS(E9-(31))<=1e-09,ABS(F9-(17))<=1e-09),"Result matches","Check the result")),"Formula error")
A10: 5 · All Hubs | G10: =IFERROR(IF(OR(ISBLANK(B10),ISBLANK(C10),ISBLANK(D10),ISBLANK(E10),ISBLANK(F10)),"Not started",IF(AND(ABS(B10-(9958))<=1e-09,ABS(C10-(22))<=1e-09,ABS(D10-(19))<=1e-09,ABS(E10-(31))<=1e-09,ABS(F10-(12))<=1e-09),"Result matches","Check the result")),"Formula error")
A12: Take-home: write your own chart-supported claim | B12: [Replace with one chart-supported sentence: state the comparison, name the measure, and cite the visible chart or table evidence without claiming causation.]
A13: Reason and chart reading | B13: [Replace with 2-4 sentences: describe the visible pattern, cite the relevant measure and units, explain what it means, and state what the chart cannot establish.]
A17: SPSS H4 evidence caption | B17: [Replace with 1-2 sentences: name the exact SPSS output, identify the statistic and population or filter you read, then state the cross-tool check you performed.]
A21: Check your work | B21: Status
A22: Part d.hub a count | B22: =IFERROR(IF('IN-CLASS_Lab Part D'!B7="","Not started",IF(ABS('IN-CLASS_Lab Part D'!B7-(3319))<=1e-09,"✓ Checked","Recheck method")),"Recheck formula")
A23: Part d.hub a median | B23: =IFERROR(IF('IN-CLASS_Lab Part D'!C7="","Not started",IF(ABS('IN-CLASS_Lab Part D'!C7-(22))<=1e-09,"✓ Checked","Recheck method")),"Recheck formula")
A24: Part d.hub a Q1 | B24: =IFERROR(IF('IN-CLASS_Lab Part D'!D7="","Not started",IF(ABS('IN-CLASS_Lab Part D'!D7-(19))<=1e-09,"✓ Checked","Recheck method")),"Recheck formula")
A25: Part d.hub a Q3 | B25: =IFERROR(IF('IN-CLASS_Lab Part D'!E7="","Not started",IF(ABS('IN-CLASS_Lab Part D'!E7-(26))<=1e-09,"✓ Checked","Recheck method")),"Recheck formula")
A26: Part d.hub a IQR | B26: =IFERROR(IF('IN-CLASS_Lab Part D'!F7="","Not started",IF(ABS('IN-CLASS_Lab Part D'!F7-(7))<=1e-09,"✓ Checked","Recheck method")),"Recheck formula")
A27: Part d.hub b count | B27: =IFERROR(IF('IN-CLASS_Lab Part D'!B8="","Not started",IF(ABS('IN-CLASS_Lab Part D'!B8-(3319))<=1e-09,"✓ Checked","Recheck method")),"Recheck formula")
A28: Part d.hub b median | B28: =IFERROR(IF('IN-CLASS_Lab Part D'!C8="","Not started",IF(ABS('IN-CLASS_Lab Part D'!C8-(22))<=1e-09,"✓ Checked","Recheck method")),"Recheck formula")
A29: Part d.hub b Q1 | B29: =IFERROR(IF('IN-CLASS_Lab Part D'!D8="","Not started",IF(ABS('IN-CLASS_Lab Part D'!D8-(19))<=1e-09,"✓ Checked","Recheck method")),"Recheck formula")
A30: Part d.hub b Q3 | B30: =IFERROR(IF('IN-CLASS_Lab Part D'!E8="","Not started",IF(ABS('IN-CLASS_Lab Part D'!E8-(26))<=1e-09,"✓ Checked","Recheck method")),"Recheck formula")
A31: Part d.hub b IQR | B31: =IFERROR(IF('IN-CLASS_Lab Part D'!F8="","Not started",IF(ABS('IN-CLASS_Lab Part D'!F8-(7))<=1e-09,"✓ Checked","Recheck method")),"Recheck formula")
A32: Part d.hub c count | B32: =IFERROR(IF('IN-CLASS_Lab Part D'!B9="","Not started",IF(ABS('IN-CLASS_Lab Part D'!B9-(3320))<=1e-09,"✓ Checked","Recheck method")),"Recheck formula")
A33: Part d.hub c median | B33: =IFERROR(IF('IN-CLASS_Lab Part D'!C9="","Not started",IF(ABS('IN-CLASS_Lab Part D'!C9-(22))<=1e-09,"✓ Checked","Recheck method")),"Recheck formula")
A34: Part d.hub c Q1 | B34: =IFERROR(IF('IN-CLASS_Lab Part D'!D9="","Not started",IF(ABS('IN-CLASS_Lab Part D'!D9-(14))<=1e-09,"✓ Checked","Recheck method")),"Recheck formula")
A35: Part d.hub c Q3 | B35: =IFERROR(IF('IN-CLASS_Lab Part D'!E9="","Not started",IF(ABS('IN-CLASS_Lab Part D'!E9-(31))<=1e-09,"✓ Checked","Recheck method")),"Recheck formula")
A36: Part d.hub c IQR | B36: =IFERROR(IF('IN-CLASS_Lab Part D'!F9="","Not started",IF(ABS('IN-CLASS_Lab Part D'!F9-(17))<=1e-09,"✓ Checked","Recheck method")),"Recheck formula")
A37: Part d.all count | B37: =IFERROR(IF('IN-CLASS_Lab Part D'!B10="","Not started",IF(ABS('IN-CLASS_Lab Part D'!B10-(9958))<=1e-09,"✓ Checked","Recheck method")),"Recheck formula")
A38: Part d.all median | B38: =IFERROR(IF('IN-CLASS_Lab Part D'!C10="","Not started",IF(ABS('IN-CLASS_Lab Part D'!C10-(22))<=1e-09,"✓ Checked","Recheck method")),"Recheck formula")
A39: Part d.all Q1 | B39: =IFERROR(IF('IN-CLASS_Lab Part D'!D10="","Not started",IF(ABS('IN-CLASS_Lab Part D'!D10-(19))<=1e-09,"✓ Checked","Recheck method")),"Recheck formula")
A40: Part d.all Q3 | B40: =IFERROR(IF('IN-CLASS_Lab Part D'!E10="","Not started",IF(ABS('IN-CLASS_Lab Part D'!E10-(31))<=1e-09,"✓ Checked","Recheck method")),"Recheck formula")
A41: Part d.all IQR | B41: =IFERROR(IF('IN-CLASS_Lab Part D'!F10="","Not started",IF(ABS('IN-CLASS_Lab Part D'!F10-(12))<=1e-09,"✓ Checked","Recheck method")),"Recheck formula")
A43: Formatting is already set. Enter your formula, then press Enter. To restore: select cell > Format Cells > Number or Custom.
A44: B7 | B44: Number, 0 decimals, records; unrelated formatting example only: stored 7 displays as 7 records. This example is not an expected answer. | Format code: 0
A45: C7 | B45: Number, 1 decimal, minutes; unrelated formatting example only: stored 7.26 displays as 7.3 minutes. This example is not an expected answer. | Format code: 0.0
A46: D7 | B46: Number, 1 decimal, minutes; unrelated formatting example only: stored 7.26 displays as 7.3 minutes. This example is not an expected answer. | Format code: 0.0
A47: E7 | B47: Number, 1 decimal, minutes; unrelated formatting example only: stored 7.26 displays as 7.3 minutes. This example is not an expected answer. | Format code: 0.0
A48: F7 | B48: Number, 1 decimal, minutes; unrelated formatting example only: stored 7.26 displays as 7.3 minutes. This example is not an expected answer. | Format code: 0.0
...

Sheet POST-CLASS_Part 1
A1: Take-home · Should we penalize Hub C, and what should the SLA say? ⏱ 60 min · at home
A2: What you're using · Section 4: The take-home reuses Parts A to D to answer the VP's two decisions. Reread: Slides 68–86; Concise Toolkit pp. 19–23; Full Toolkit pp. 70–94
A3: P₉₅ = value at rank 0.95 (n+1) of the sorted valid latencies = B8 where C = Hub C · n_C = Hub C valid orders · P₉₅ = 95th percentile of valid latency, all hubs · x_C, x_C = Hub C mean and median
A4: ="Progress: "&COUNTIF(B38:B45,"✓ Checked")&" of 8 checked. Save after each ✓."
A5: Open POST-CLASS_Part 1!A7. Save as LAB01_FirstName_LastName_NetID.xlsx and continue to the Brightspace Lab #1 Assignment Submission Portal.
A7: 1 · All-hubs valid latency records | C7: =IFERROR(IF(OR(ISBLANK(B7)),"Not started",IF(AND(ABS(B7-(9958))<=1e-09),"Result matches","Check the result")),"Formula error") | E7: All-hubs valid latency records. Use the completed Parts and the stated units.. Do not report 10,000 as the latency denominator if sentinels are excluded.
A8: 2 · All-hubs 95th percentile | C8: =IFERROR(IF(OR(ISBLANK(B8)),"Not started",IF(AND(ABS(B8-(50))<=1e-09),"Result matches","Check the result")),"Formula error") | E8: All-hubs 95th percentile. Use the completed Parts and the stated units.. Use Number format; this percentile result is minutes, not a percentage.
A9: 3 · Hub C valid latency records | C9: =IFERROR(IF(OR(ISBLANK(B9)),"Not started",IF(AND(ABS(B9-(3320))<=1e-09),"Result matches","Check the result")),"Formula error") | E9: Hub C valid latency records. Use the completed Parts and the stated units.. Do not omit the hub criterion or use the all-hubs denominator.
A10: 4 · Hub C mean latency | C10: =IFERROR(IF(OR(ISBLANK(B10)),"Not started",IF(AND(ABS(B10-(29.9370481927711))<=0.0598740963855422),"Result matches","Check the result")),"Formula error") | E10: Hub C mean latency. Use the completed Parts and the stated units.. Do not report the mean without B9 and the minute unit.
A11: 5 · Hub C median latency | C11: =IFERROR(IF(OR(ISBLANK(B11)),"Not started",IF(AND(ABS(B11-(22))<=1e-09),"Result matches","Check the result")),"Formula error") | E11: Hub C median latency. Use the completed Parts and the stated units.. Do not call the median the mean.
A12: 6 · Hub C 95th percentile | C12: =IFERROR(IF(OR(ISBLANK(B12)),"Not started",IF(AND(ABS(B12-(50))<=1e-09),"Result matches","Check the result")),"Formula error") | E12: Hub C 95th percentile. Use the completed Parts and the stated units.. Do not format the threshold as Percentage.
A13: 7 · Hub C mean-minus-median gap | C13: =IFERROR(IF(OR(ISBLANK(B13)),"Not started",IF(AND(ABS(B13-(7.93704819277108))<=0.0158740963855422),"Result matches","Check the result")),"Formula error") | E13: Hub C mean-minus-median gap. Use the completed Parts and the stated units.. This gap does not identify the cause of the upper tail.
A14: 8 · Hub C share above overall P95 | C14: =IFERROR(IF(OR(ISBLANK(B14)),"Not started",IF(AND(ABS(B14-(0.038855421686747))<=0.0015),"Result matches","Check the result")),"Formula error") | E14: Hub C share above overall P95. Use the completed Parts and the stated units.. Do not multiply the fraction by 100 and then apply Percentage format.
A16: Evidence defense | B16: [Replace with 1-2 short paragraphs: identify evidence for typical service, variability, and upper-tail risk; include each value, unit, denominator, meaning, and one limitation.]
A21: Workbook recommendation source | B21: [Replace with 1-2 short paragraphs: state the decision and recommended action, cite the key evidence with units and denominator, state one limitation, and name the next evidence needed.]
A26: SPSS H5 evidence caption | B26: [Replace with 1-2 sentences: name the exact SPSS output, identify the statistic and population or filter you read, then state the cross-tool check you performed.]
A29: Memo evidence map (planning only) | B29: [Replace with one line per memo claim: state the claim, then point to the exact workbook sheet and cell or named SPSS output that supports it.]
A33: AI-use or non-use disclosure | B33: [Replace with either No AI used, or identify the tool, purpose, material adopted or revised, and the checks you performed.]
A37: Check your work | B37: Status
A38: Take home.all valid count | B38: =IFERROR(IF('POST-CLASS_Part 1'!B7="","Not started",IF(ABS('POST-CLASS_Part 1'!B7-(9958))<=1e-09,"✓ Checked","Recheck method")),"Recheck formula")
A39: Take home.all P95 | B39: =IFERROR(IF('POST-CLASS_Part 1'!B8="","Not started",IF(ABS('POST-CLASS_Part 1'!B8-(50))<=1e-09,"✓ Checked","Recheck method")),"Recheck formula")
A40: Take home.hub c valid count | B40: =IFERROR(IF('POST-CLASS_Part 1'!B9="","Not started",IF(ABS('POST-CLASS_Part 1'!B9-(3320))<=1e-09,"✓ Checked","Recheck method")),"Recheck formula")
A41: Take home.hub c mean | B41: =IFERROR(IF('POST-CLASS_Part 1'!B10="","Not started",IF(ABS('POST-CLASS_Part 1'!B10-(29.9370481927711))<=0.0598740963855422,"✓ Checked","Recheck method")),"Recheck formula")
A42: Take home.hub c median | B42: =IFERROR(IF('POST-CLASS_Part 1'!B11="","Not started",IF(ABS('POST-CLASS_Part 1'!B11-(22))<=1e-09,"✓ Checked","Recheck method")),"Recheck formula")
A43: Take home.hub c P95 | B43: =IFERROR(IF('POST-CLASS_Part 1'!B12="","Not started",IF(ABS('POST-CLASS_Part 1'!B12-(50))<=1e-09,"✓ Checked","Recheck method")),"Recheck formula")
A44: Take home.hub c mean median gap | B44: =IFERROR(IF('POST-CLASS_Part 1'!B13="","Not started",IF(ABS('POST-CLASS_Part 1'!B13-(7.93704819277108))<=0.0158740963855422,"✓ Checked","Recheck method")),"Recheck formula")
A45: Take home.hub c share above all P95 | B45: =IFERROR(IF('POST-CLASS_Part 1'!B14="","Not started",IF(ABS('POST-CLASS_Part 1'!B14-(0.038855421686747))<=0.0015,"✓ Checked","Recheck method")),"Recheck formula")
A47: Formatting is already set. Enter your formula, then press Enter. To restore: select cell > Format Cells > Number or Custom.
A48: B7 | B48: Number, 0 decimals, records; unrelated formatting example only: stored 7 displays as 7 records. This example is not an expected answer. | Format code: 0
A49: B8 | B49: Number, 1 decimal, minutes; unrelated formatting example only: stored 7.26 displays as 7.3 minutes. This example is not an expected answer. | Format code: 0.0
A50: B9 | B50: Number, 0 decimals, records; unrelated formatting example only: stored 7 displays as 7 records. This example is not an expected answer. | Format code: 0
A51: B10 | B51: Number, 1 decimal, minutes; unrelated formatting example only: stored 7.26 displays as 7.3 minutes. This example is not an expected answer. | Format code: 0.0
A52: B11 | B52: Number, 1 decimal, minutes; unrelated formatting example only: stored 7.26 displays as 7.3 minutes. This example is not an expected answer. | Format code: 0.0
A53: B12 | B53: Number, 1 decimal, minutes; unrelated formatting example only: stored 7.26 displays as 7.3 minutes. This example is not an expected answer. | Format code: 0.0
A54: B13 | B54: Number, 1 decimal, minutes; unrelated formatting example only: stored 7.26 displays as 7.3 minutes. This example is not an expected answer. | Format code: 0.0
A55: B14 | B55: Percentage, 1 decimal; unrelated formatting example only: stored 0.125 displays as 12.5%. Enter the fraction formula; do not multiply by 100. This example is not an expected answer. | Format code: 0.0%
A57: ⚠ Most common mistake: Writing that Hub C caused the delays, or reporting the B14 share without its denominator. These are descriptive summaries of one extract. Say "of Hub C's valid orders" and name what else could explain a gap.

Sheet Data
A1: OrderID | B1: CustomerID | C1: OrderTier | D1: Hub | E1: Age_Years | F1: Latency_Minutes | H1: Shared data: orders_story.csv | J1: OrderTier is ratio-scale because its codes can be divided meaningfully. | K1: A mean above the median proves that Hub C caused the largest delays. | L1: Every value above the upper fence should be deleted before reporting latency.
A2: ORD00001 | B2: C0001 | C2: 1 | D2: Hub A | E2: 25 | F2: 19 | H2: Excel: use the table on this sheet. SPSS: use the supplied .sps import. | J2: OrderTier is nominal because the three codes have no meaningful order. | K2: A mean above the median is consistent with an upper tail, but it does not identify a cause. | L2: A Tukey flag proves that a regional carrier caused the recorded delay.
A3: ORD00002 | B3: C0002 | C3: 2 | D3: Hub A | E3: 32 | F3: 19 | H3: Python/R: read the matching CSV with the types and missing rules below. | J3: OrderTier is ordinal, so ranks and a median are admissible but an arithmetic mean is not. | K3: A mean above the median means every valid order exceeded the median. | L3: A value below the lower fence must be replaced with the median.
A4: ORD00003 | B4: C0003 | C4: 3 | D4: Hub A | E4: 39 | F4: 19 | H4: OrderID | text | Unique identifier for one recorded order. | units: identifier | missing: blank [] | J4: OrderTier is interval-scale because adjacent stored codes differ by one. | K4: A large sample standard deviation proves the latency distribution is normal. | L4: A Tukey flag identifies an unusual observation for investigation but does not establish invalidity or cause.
A5: ORD00004 | B5: C0004 | C5: 1 | D5: Hub A | E5: 46 | F5: 19 | H5: CustomerID | text | Customer identifier; repeated values represent multiple recorded orders. | units: identifier | missing: blank []
A6: ORD00005 | B6: C0005 | C6: 2 | D6: Hub A | E6: 53 | F6: 19 | H6: OrderTier | integer | Ordered service tier coded 1, 2 or 3; arithmetic means are not admissible. | units: ordinal tier | missing: blank []
A7: ORD00006 | B7: C0006 | C7: 3 | D7: Hub A | E7: 60 | F7: 19 | H7: Hub | text | Regional fulfillment hub recorded as Hub A, Hub B or Hub C. | units: category | missing: blank []
A8: ORD00007 | B8: C0007 | C8: 1 | D8: Hub A | E8: 67 | F8: 19 | H8: Age_Years | integer | Recorded customer age; -1 is a source sentinel and is missing only for age analysis. | units: years | missing: blank [-1]
A9: ORD00008 | B9: C0008 | C9: 2 | D9: Hub A | E9: 74 | F9: 19 | H9: Latency_Minutes | number | Recorded fulfillment latency; 999 is a source sentinel and is missing only for latency analysis. | units: minutes | missing: blank [999]
A10: ORD00009 | B10: C0009 | C10: 3 | D10: Hub A | E10: 21 | F10: 19
A11: ORD00010 | B11: C0010 | C11: 1 | D11: Hub A | E11: 28 | F11: 19
A12: ORD00011 | B12: C0011 | C12: 2 | D12: Hub A | E12: 35 | F12: 19
A13: ORD00012 | B13: C0012 | C13: 3 | D13: Hub A | E13: 42 | F13: 19
A14: ORD00013 | B14: C0013 | C14: 1 | D14: Hub A | E14: 49 | F14: 19
A15: ORD00014 | B15: C0014 | C15: 2 | D15: Hub A | E15: 56 | F15: 19
A16: ORD00015 | B16: C0015 | C16: 3 | D16: Hub A | E16: 63 | F16: 19
A17: ORD00016 | B17: C0016 | C17: 1 | D17: Hub A | E17: 70 | F17: 19
A18: ORD00017 | B18: C0017 | C18: 2 | D18: Hub A | E18: 77 | F18: 19
A19: ORD00018 | B19: C0018 | C19: 3 | D19: Hub A | E19: 24 | F19: 19
A20: ORD00019 | B20: C0019 | C20: 1 | D20: Hub A | E20: 31 | F20: 19
A21: ORD00020 | B21: C0020 | C21: 2 | D21: Hub A | E21: 38 | F21: 19
... A10001: ORD10000 | B10001: C2500 | C10001: 3 | D10001: Hub C | E10001: -1 | F10001: 999
