Workbook
Name LabChoices_1: 'Data'!$I$1:$I$4
Name LabChoices_2: 'Data'!$J$1:$J$4
Name LabChoices_3: 'Data'!$K$1:$K$4

Sheet Start Here
A1: Welcome to S05P
A2: Does Cedar Loop's pickup delay rate warrant immediate permanent staffing or a bounded audit pilot?
A4: 1. Your details
A5: First name | D5: Last name | G5: NYU NetID
A7: Your NetID is the username before @nyu.edu in your NYU email address. For example, jd1234@nyu.edu uses jd1234. Enter only the NetID here.
A8: Use your own details. For example only: first name Jane, last name Doe, NetID jd1234 gives S05P_Jane_Doe_jd1234.xlsx. Keep hyphens in names; filenames omit spaces and unsupported punctuation.
A10: 2. Your working filenames
A11: =IF(OR(LEN(TRIM(A6))=0,LEN(TRIM(D6))=0,LEN(TRIM(G6))=0),"Enter all three fields above to show your filenames.",IF(OR(ISNUMBER(SEARCH("@",G6)),ISNUMBER(SEARCH(" ",TRIM(G6))),AND(LEFT(UPPER(TRIM(G6)),1)="N",ISNUMBER(IFERROR(VALUE(MID(TRIM(G6),2,99)),"")))),"Enter only your NYU NetID, not your full email address or N-number.","Use File > Save As with the workbook name below. Optional SPSS working copies may use the matching names.")) -> Enter all three fields above to show your filenames.
A13: Excel workbook | C13: =IF(LEFT(A11,3)="Use","S05P_"&SUBSTITUTE(SUBSTITUTE(SUBSTITUTE(SUBSTITUTE(SUBSTITUTE(SUBSTITUTE(SUBSTITUTE(SUBSTITUTE(SUBSTITUTE(SUBSTITUTE(TRIM(A6)," ",""),"/",""),"\",""),":",""),"*",""),"?",""),"""",""),"<",""),">",""),"|","")&"_"&SUBSTITUTE(SUBSTITUTE(SUBSTITUTE(SUBSTITUTE(SUBSTITUTE(SUBSTITUTE(SUBSTITUTE(SUBSTITUTE(SUBSTITUTE(SUBSTITUTE(TRIM(D6)," ",""),"/",""),"\",""),":",""),"*",""),"?",""),"""",""),"<",""),">",""),"|","")&"_"&LOWER(TRIM(G6))&".xlsx","")
A14: SPSS syntax | C14: =IF(LEFT(A11,3)="Use","S05P_"&SUBSTITUTE(SUBSTITUTE(SUBSTITUTE(SUBSTITUTE(SUBSTITUTE(SUBSTITUTE(SUBSTITUTE(SUBSTITUTE(SUBSTITUTE(SUBSTITUTE(TRIM(A6)," ",""),"/",""),"\",""),":",""),"*",""),"?",""),"""",""),"<",""),">",""),"|","")&"_"&SUBSTITUTE(SUBSTITUTE(SUBSTITUTE(SUBSTITUTE(SUBSTITUTE(SUBSTITUTE(SUBSTITUTE(SUBSTITUTE(SUBSTITUTE(SUBSTITUTE(TRIM(D6)," ",""),"/",""),"\",""),":",""),"*",""),"?",""),"""",""),"<",""),">",""),"|","")&"_"&LOWER(TRIM(G6))&".sps","")
A15: SPSS output | C15: =IF(LEFT(A11,3)="Use","S05P_"&SUBSTITUTE(SUBSTITUTE(SUBSTITUTE(SUBSTITUTE(SUBSTITUTE(SUBSTITUTE(SUBSTITUTE(SUBSTITUTE(SUBSTITUTE(SUBSTITUTE(TRIM(A6)," ",""),"/",""),"\",""),":",""),"*",""),"?",""),"""",""),"<",""),">",""),"|","")&"_"&SUBSTITUTE(SUBSTITUTE(SUBSTITUTE(SUBSTITUTE(SUBSTITUTE(SUBSTITUTE(SUBSTITUTE(SUBSTITUTE(SUBSTITUTE(SUBSTITUTE(TRIM(D6)," ",""),"/",""),"\",""),":",""),"*",""),"?",""),"""",""),"<",""),">",""),"|","")&"_"&LOWER(TRIM(G6))&".spv","")
A19: Save one personalized workbook for this ungraded practice. SPSS syntax and output copies are optional working evidence. No memo, upload, submission or deadline is required.
A21: 3. Learn, check and save
A22: Yellow cells are for your work. Read the study-help column beside response rows for relevant slides, concise toolkit pages and an optional question you can ask AI.
A23: AI help is optional and follows the lab’s permitted-use timing. Ask for a different practice example and check its explanation. This practice has no submission.
A24: Use the guide for exact software steps. A matching number still needs an explanation. Save at each checkpoint. Your filenames update here, but this sheet does not rename or submit files.
A26: Open a Part
A27: IN-CLASS_Lab Part A: Sampling Frame and Nonresponse Audit
A28: IN-CLASS_Lab Part B: Duration Estimation and Confidence Intervals
A29: IN-CLASS_Lab Part C: Proportion Confidence Interval and Sample Size Planning

Sheet IN-CLASS_Lab Part A
A1: Part A · Sampling Frame and Nonresponse Audit ⏱ 10 min · from slide 28 → back to slide 29
A2: What you're using · Section 1: A target population is the complete group of decision interest, while the sampling frame is the concrete operational list used to draw units. Reread: Slides 9–28; Concise Toolkit pp. 4-10; Full Toolkit pp. 4-22
A3: N = \text{Total audited frame units}
A4: ="Progress: "&COUNTIF(B21:B26,"✓ Checked")&" of 6 checked. Save after each ✓."
A5: Open 'IN-CLASS_Lab Part A'!B7. Save the same S05P_FirstName_LastName_NetID.xlsx workbook. | I5: Study help (optional) Read the pages, then use the AI question if useful.
A7: 1 · Invited pickups | C7: =IFERROR(IF(OR(ISBLANK(B7)),"Not started",IF(AND(ABS(B7-(125))<=1e-09),"Result matches","Check the result")),"Formula error") | E7: Invited pickups. Practice check: 125; use the cell's stated units. Counting respondents alone excludes invited nonrespondents. | I7: B7: Slides 10-11. Concise Toolkit pp. 3-9 After-class AI question: Explain Target Population and Sampling Frame. Use a different example, then ask me one check question.
A8: 2 · Eligible respondents | C8: =IFERROR(IF(OR(ISBLANK(B8)),"Not started",IF(AND(ABS(B8-(100))<=1e-09),"Result matches","Check the result")),"Formula error") | E8: Eligible respondents. Practice check: 100; use the cell's stated units. A numeric zero criterion can match blank cells; require a nonblank outcome in the zero branch. Missing outcomes are not on-time pickups. | I8: B8: Slides 21-23. Concise Toolkit pp. 3-9 After-class AI question: Explain Nonresponse Sensitivity Bounds. Use a different example, then ask me one check question.
A9: 3 · Delayed respondents | C9: =IFERROR(IF(OR(ISBLANK(B9)),"Not started",IF(AND(ABS(B9-(24))<=1e-09),"Result matches","Check the result")),"Formula error") | E9: Delayed respondents. Practice check: 24; use the cell's stated units. Counting 1s without applying the respondent-status criterion. | I9: B9: Slides 21-23. Concise Toolkit pp. 3-9 After-class AI question: Explain Nonresponse Sensitivity Bounds. Use a different example, then ask me one check question.
A10: 4 · Respondent delay rate | C10: =IFERROR(IF(OR(ISBLANK(B10)),"Not started",IF(AND(ABS(B10-(0.24))<=0.0015),"Result matches","Check the result")),"Formula error") | E10: Respondent delay rate. Practice check: 24.0%; use the cell's stated units. Using all invitations as this respondent rate's denominator or multiplying by 100 before Percent format. | I10: B10: Slides 21-23. Concise Toolkit pp. 3-9 After-class AI question: Explain Nonresponse Sensitivity Bounds. Use a different example, then ask me one check question.
A11: 5 · Best-case invitation bound | C11: =IFERROR(IF(OR(ISBLANK(B11)),"Not started",IF(AND(ABS(B11-(0.192))<=0.0015),"Result matches","Check the result")),"Formula error") | E11: Best-case invitation bound. Practice check: 19.2%; use the cell's stated units. Dividing by observed responses instead of invitations. | I11: B11: Slides 21-23. Concise Toolkit pp. 3-9 After-class AI question: Explain Nonresponse Sensitivity Bounds. Use a different example, then ask me one check question.
A12: 6 · Worst-case invitation bound | C12: =IFERROR(IF(OR(ISBLANK(B12)),"Not started",IF(AND(ABS(B12-(0.392))<=0.0015),"Result matches","Check the result")),"Formula error") | E12: Worst-case invitation bound. Practice check: 39.2%; use the cell's stated units. Adding all blank flags from the frame, including not-invited rows. | I12: B12: Slides 21-23. Concise Toolkit pp. 3-9 After-class AI question: Explain Nonresponse Sensitivity Bounds. Use a different example, then ask me one check question.
A14: Select an interpretation | I14: B14: Slides 10-11. Concise Toolkit pp. 3-9 After-class AI question: Explain Sampling Frame and Nonresponse Audit. Use a different example, then ask me one check question.
A15: Your denominator-based reason | B15: [Replace with your reason: identify the respondent denominator, invitation denominator and what remains unobserved.] | I15: B15: Slides 10-11. Concise Toolkit pp. 3-9 After-class AI question: Explain Sampling Frame and Nonresponse Audit. Use a different example, then ask me one check question.
A20: Check your work | B20: Status
A21: A invited | B21: =IFERROR(IF(OR(ISBLANK('IN-CLASS_Lab Part A'!B7)),"Not started",IF(AND(ABS('IN-CLASS_Lab Part A'!B7-(125))<=1e-09),"✓ Checked","Check the result")),"Formula error")
A22: A eligible | B22: =IFERROR(IF(OR(ISBLANK('IN-CLASS_Lab Part A'!B8)),"Not started",IF(AND(ABS('IN-CLASS_Lab Part A'!B8-(100))<=1e-09),"✓ Checked","Check the result")),"Formula error")
A23: A delayed | B23: =IFERROR(IF(OR(ISBLANK('IN-CLASS_Lab Part A'!B9)),"Not started",IF(AND(ABS('IN-CLASS_Lab Part A'!B9-(24))<=1e-09),"✓ Checked","Check the result")),"Formula error")
A24: A respondent rate | B24: =IFERROR(IF(OR(ISBLANK('IN-CLASS_Lab Part A'!B10)),"Not started",IF(AND(ABS('IN-CLASS_Lab Part A'!B10-(0.24))<=0.0015),"✓ Checked","Check the result")),"Formula error")
A25: A lower scenario | B25: =IFERROR(IF(OR(ISBLANK('IN-CLASS_Lab Part A'!B11)),"Not started",IF(AND(ABS('IN-CLASS_Lab Part A'!B11-(0.192))<=0.0015),"✓ Checked","Check the result")),"Formula error")
A26: A upper scenario | B26: =IFERROR(IF(OR(ISBLANK('IN-CLASS_Lab Part A'!B12)),"Not started",IF(AND(ABS('IN-CLASS_Lab Part A'!B12-(0.392))<=0.0015),"✓ Checked","Check the result")),"Formula error")
A28: Formatting is already set. Enter your formula, then press Enter. To restore: select cell > Format Cells > Number or Custom.
A29: B7 | B29: Number, 0 decimals, pickups; unrelated formatting example only: stored 7 displays as 7 pickups. This is not a check value. | Format code: 0
A30: B8 | B30: Number, 0 decimals, pickups; unrelated formatting example only: stored 7 displays as 7 pickups. This is not a check value. | Format code: 0
A31: B9 | B31: Number, 0 decimals, pickups; unrelated formatting example only: stored 7 displays as 7 pickups. This is not a check value. | Format code: 0
A32: B10 | B32: Percentage, 1 decimal, percent of eligible respondents; unrelated formatting example only: stored 0.125 displays as 12.5%. This is not a check value. | Format code: 0.0%
A33: B11 | B33: Percentage, 1 decimal, percent of invited pickups; unrelated formatting example only: stored 0.125 displays as 12.5%. This is not a check value. | Format code: 0.0%
A34: B12 | B34: Percentage, 1 decimal, percent of invited pickups; unrelated formatting example only: stored 0.125 displays as 12.5%. This is not a check value. | Format code: 0.0%

Sheet IN-CLASS_Lab Part B
A1: Part B · Duration Estimation and Confidence Intervals ⏱ 10 min · from slide 46 → back to slide 47
A2: What you're using · Section 2: The standard error measures the expected variability of sample means across repeated samples of size n drawn from the same population. Reread: Slides 29–46; Concise Toolkit pp. 11-18; Full Toolkit pp. 23-41
A3: \text{SE}_{\bar{x}} = \frac{s}{\sqrt{n}}
A4: ="Progress: "&COUNTIF(B21:B26,"✓ Checked")&" of 6 checked. Save after each ✓."
A5: Open 'IN-CLASS_Lab Part B'!B7. Save the same S05P_FirstName_LastName_NetID.xlsx workbook. | I5: Study help (optional) Read the pages, then use the AI question if useful.
A7: 1 · Observed mean duration | C7: =IFERROR(IF(OR(ISBLANK(B7)),"Not started",IF(AND(ABS(B7-(42))<=1e-09),"Result matches","Check the result")),"Formula error") | E7: Observed mean duration. Practice check: 42.00; use the cell's stated units. Replacing blank durations with zero. | I7: B7: Slides 36-38. Concise Toolkit pp. 10-17 After-class AI question: Explain Student t Confidence Interval for a Mean. Use a different example, then ask me one check question.
A8: 2 · Sample duration SD | C8: =IFERROR(IF(OR(ISBLANK(B8)),"Not started",IF(AND(ABS(B8-(12))<=0.024),"Result matches","Check the result")),"Formula error") | E8: Sample duration SD. Practice check: 12.00; use the cell's stated units. Using STDEV.P or interpreting SD as the standard error. | I8: B8: Slides 31-32. Concise Toolkit pp. 10-17 After-class AI question: Explain Standard Error of the Mean. Use a different example, then ask me one check question.
A9: 3 · Standard error | C9: =IFERROR(IF(OR(ISBLANK(B9)),"Not started",IF(AND(ABS(B9-(1.2))<=0.0024),"Result matches","Check the result")),"Formula error") | E9: Standard error. Practice check: 1.20; use the cell's stated units. Dividing sample SD by n instead of √n. | I9: B9: Slides 31-32. Concise Toolkit pp. 10-17 After-class AI question: Explain Standard Error of the Mean. Use a different example, then ask me one check question.
A10: 5 · Lower 95% mean limit | C10: =IFERROR(IF(OR(ISBLANK(B10)),"Not started",IF(AND(ABS(B10-(39.6189396580963))<=0.0792378793161926),"Result matches","Check the result")),"Formula error") | E10: Lower 95% mean limit. Practice check: 39.62; use the cell's stated units. Reading it as a minimum observed or individual pickup duration. | I10: B10: Slides 36-38. Concise Toolkit pp. 10-17 After-class AI question: Explain Student t Confidence Interval for a Mean. Use a different example, then ask me one check question.
A11: 6 · Upper 95% mean limit | C11: =IFERROR(IF(OR(ISBLANK(B11)),"Not started",IF(AND(ABS(B11-(44.3810603419037))<=0.0887621206838074),"Result matches","Check the result")),"Formula error") | E11: Upper 95% mean limit. Practice check: 44.38; use the cell's stated units. Calling this an upper limit for individual pickups. | I11: B11: Slides 36-38. Concise Toolkit pp. 10-17 After-class AI question: Explain Student t Confidence Interval for a Mean. Use a different example, then ask me one check question.
A12: 4 · Two-sided t multiplier | C12: =IFERROR(IF(OR(ISBLANK(B12)),"Not started",IF(AND(ABS(B12-(1.98421695158642))<=0.00396843390317283),"Result matches","Check the result")),"Formula error") | E12: Two-sided t multiplier. Practice check: 1.9842; use the cell's stated units. Using n rather than n−1 degrees of freedom or a one-tailed critical value. | I12: B12: Slides 36-38. Concise Toolkit pp. 10-17 After-class AI question: Explain Student t Confidence Interval for a Mean. Use a different example, then ask me one check question.
A14: Select an interpretation | I14: B14: Slides 35, 39-40. Concise Toolkit pp. 10-17 After-class AI question: Explain Duration Estimation and Confidence Intervals. Use a different example, then ask me one check question.
A15: Your SE and target reason | B15: [Replace with your reason: describe what SE measures, compare the mean interval with the target and state one limitation.] | I15: B15: Slides 35, 39-40. Concise Toolkit pp. 10-17 After-class AI question: Explain Duration Estimation and Confidence Intervals. Use a different example, then ask me one check question.
A20: Check your work | B20: Status
A21: B mean | B21: =IFERROR(IF(OR(ISBLANK('IN-CLASS_Lab Part B'!B7)),"Not started",IF(AND(ABS('IN-CLASS_Lab Part B'!B7-(42))<=1e-09),"✓ Checked","Check the result")),"Formula error")
A22: B sample standard deviation | B22: =IFERROR(IF(OR(ISBLANK('IN-CLASS_Lab Part B'!B8)),"Not started",IF(AND(ABS('IN-CLASS_Lab Part B'!B8-(12))<=0.024),"✓ Checked","Check the result")),"Formula error")
A23: B standard error | B23: =IFERROR(IF(OR(ISBLANK('IN-CLASS_Lab Part B'!B9)),"Not started",IF(AND(ABS('IN-CLASS_Lab Part B'!B9-(1.2))<=0.0024),"✓ Checked","Check the result")),"Formula error")
A24: B lower mean | B24: =IFERROR(IF(OR(ISBLANK('IN-CLASS_Lab Part B'!B10)),"Not started",IF(AND(ABS('IN-CLASS_Lab Part B'!B10-(39.6189396580963))<=0.0792378793161926),"✓ Checked","Check the result")),"Formula error")
A25: B upper mean | B25: =IFERROR(IF(OR(ISBLANK('IN-CLASS_Lab Part B'!B11)),"Not started",IF(AND(ABS('IN-CLASS_Lab Part B'!B11-(44.3810603419037))<=0.0887621206838074),"✓ Checked","Check the result")),"Formula error")
A26: B t critical | B26: =IFERROR(IF(OR(ISBLANK('IN-CLASS_Lab Part B'!B12)),"Not started",IF(AND(ABS('IN-CLASS_Lab Part B'!B12-(1.98421695158642))<=0.00396843390317283),"✓ Checked","Check the result")),"Formula error")
A28: Formatting is already set. Enter your formula, then press Enter. To restore: select cell > Format Cells > Number or Custom.
A29: B7 | B29: Number, 2 decimals, minutes; unrelated formatting example only: stored 7.256 displays as 7.26 minutes. This is not a check value. | Format code: 0.00
A30: B8 | B30: Number, 2 decimals, minutes; unrelated formatting example only: stored 7.256 displays as 7.26 minutes. This is not a check value. | Format code: 0.00
A31: B9 | B31: Number, 2 decimals, minutes; unrelated formatting example only: stored 7.256 displays as 7.26 minutes. This is not a check value. | Format code: 0.00
A32: B10 | B32: Number, 2 decimals, minutes; unrelated formatting example only: stored 7.256 displays as 7.26 minutes. This is not a check value. | Format code: 0.00
A33: B11 | B33: Number, 2 decimals, minutes; unrelated formatting example only: stored 7.256 displays as 7.26 minutes. This is not a check value. | Format code: 0.00
A34: B12 | B34: Number, 4 decimals, unitless; unrelated formatting example only: stored 1.23456 displays as 1.2346. This is not a check value. | Format code: 0.0000

Sheet IN-CLASS_Lab Part C
A1: Part C · Proportion Confidence Interval and Sample Size Planning ⏱ 10 min · from slide 66 → back to slide 70 then ⏱ 15 min · at home
A2: What you're using · Section 3: A proportion confidence interval bounds the true population share of binary events using the normal approximation. Reread: Slides 48–66; Concise Toolkit pp. 19-26; Full Toolkit pp. 42-59
A3: \hat{p} \pm z^* \sqrt{\frac{\hat{p}(1 - \hat{p})}{n}}
A4: ="Progress: "&COUNTIF(B23:B28,"✓ Checked")&" of 6 checked. Save after each ✓."
A5: Open 'IN-CLASS_Lab Part C'!B7. Save the same S05P_FirstName_LastName_NetID.xlsx workbook. | I5: Study help (optional) Read the pages, then use the AI question if useful.
A7: 1 · Eligible recorded outcomes | C7: =IFERROR(IF(OR(ISBLANK(B7)),"Not started",IF(AND(ABS(B7-(100))<=1e-09),"Result matches","Check the result")),"Formula error") | E7: Eligible recorded outcomes. Practice check: 100; use the cell's stated units. A numeric zero criterion can match blank cells; require a nonblank outcome in the zero branch. Missing outcomes are not on-time pickups. | I7: B7: Slides 51-53. Concise Toolkit pp. 18-26 After-class AI question: Explain Confidence Interval for a Population Proportion. Use a different example, then ask me one check question.
A8: 2 · Recorded delay outcomes | C8: =IFERROR(IF(OR(ISBLANK(B8)),"Not started",IF(AND(ABS(B8-(24))<=1e-09),"Result matches","Check the result")),"Formula error") | E8: Recorded delay outcomes. Practice check: 24; use the cell's stated units. Changing the case’s 50-minute delay definition or counting missing outcomes as on-time. | I8: B8: Slides 51-53. Concise Toolkit pp. 18-26 After-class AI question: Explain Confidence Interval for a Population Proportion. Use a different example, then ask me one check question.
A9: 3 · Observed delay share | C9: =IFERROR(IF(OR(ISBLANK(B9)),"Not started",IF(AND(ABS(B9-(0.24))<=0.0015),"Result matches","Check the result")),"Formula error") | E9: Observed delay share. Practice check: 24.0%; use the cell's stated units. Multiplying by 100 and then applying Percentage format. | I9: B9: Slides 51-53. Concise Toolkit pp. 18-26 After-class AI question: Explain Confidence Interval for a Population Proportion. Use a different example, then ask me one check question.
A10: 4 · Lower 95% share limit | C10: =IFERROR(IF(OR(ISBLANK(B10)),"Not started",IF(AND(ABS(B10-(0.156291706504075))<=0.0015),"Result matches","Check the result")),"Formula error") | E10: Lower 95% share limit. Practice check: 15.63%; use the cell's stated units. Using all invitations as the observed-outcome denominator. | I10: B10: Slides 51-53. Concise Toolkit pp. 18-26 After-class AI question: Explain Confidence Interval for a Population Proportion. Use a different example, then ask me one check question.
A11: 5 · Upper 95% share limit | C11: =IFERROR(IF(OR(ISBLANK(B11)),"Not started",IF(AND(ABS(B11-(0.323708293495925))<=0.0015),"Result matches","Check the result")),"Formula error") | E11: Upper 95% share limit. Practice check: 32.37%; use the cell's stated units. Treating a 95% interval as proof of an operational or causal effect. | I11: B11: Slides 51-53. Concise Toolkit pp. 18-26 After-class AI question: Explain Confidence Interval for a Population Proportion. Use a different example, then ask me one check question.
A12: 6 · Required completed pickups | C12: =IFERROR(IF(OR(ISBLANK(B12)),"Not started",IF(AND(ABS(B12-(438))<=1e-09),"Result matches","Check the result")),"Formula error") | E12: Required completed pickups. Practice check: 438; use the cell's stated units. Rounding down or treating a four-percentage-point margin as a 4% relative change. | I12: B12: Slides 56, 61-62. Concise Toolkit pp. 18-26 After-class AI question: Explain Sample Size Planning for Precision. Use a different example, then ask me one check question.
A13: Select an interpretation | I13: B13: Slides 51-53. Concise Toolkit pp. 18-26 After-class AI question: Explain Proportion Confidence Interval and Sample Size Planning. Use a different example, then ask me one check question.
A14: Your precision reason | B14: [Replace with your reason: distinguish completed outcomes from invitations and identify what precision cannot repair.] | I14: B14: Slides 51-53. Concise Toolkit pp. 18-26 After-class AI question: Explain Proportion Confidence Interval and Sample Size Planning. Use a different example, then ask me one check question.
A15: POST-CLASS, 15 minutes: your decision revisit | B15: [Replace with your own Option A versus Option B recommendation. Option A = immediate permanent staffing; Option B = a bounded audit pilot. Cite invitation bounds, both intervals, the completed-sample target, one limitation, and a condition that would change your choice.] | I15: B15: Slides 51-53. Concise Toolkit pp. 18-26 After-class AI question: Explain Proportion Confidence Interval and Sample Size Planning. Use a different example, then ask me one check question.
A22: Check your work | B22: Status
A23: C eligible | B23: =IFERROR(IF(OR(ISBLANK('IN-CLASS_Lab Part C'!B7)),"Not started",IF(AND(ABS('IN-CLASS_Lab Part C'!B7-(100))<=1e-09),"✓ Checked","Check the result")),"Formula error")
A24: C slow | B24: =IFERROR(IF(OR(ISBLANK('IN-CLASS_Lab Part C'!B8)),"Not started",IF(AND(ABS('IN-CLASS_Lab Part C'!B8-(24))<=1e-09),"✓ Checked","Check the result")),"Formula error")
A25: C share | B25: =IFERROR(IF(OR(ISBLANK('IN-CLASS_Lab Part C'!B9)),"Not started",IF(AND(ABS('IN-CLASS_Lab Part C'!B9-(0.24))<=0.0015),"✓ Checked","Check the result")),"Formula error")
A26: C lower share | B26: =IFERROR(IF(OR(ISBLANK('IN-CLASS_Lab Part C'!B10)),"Not started",IF(AND(ABS('IN-CLASS_Lab Part C'!B10-(0.156291706504075))<=0.0015),"✓ Checked","Check the result")),"Formula error")
A27: C upper share | B27: =IFERROR(IF(OR(ISBLANK('IN-CLASS_Lab Part C'!B11)),"Not started",IF(AND(ABS('IN-CLASS_Lab Part C'!B11-(0.323708293495925))<=0.0015),"✓ Checked","Check the result")),"Formula error")
A28: C completed target | B28: =IFERROR(IF(OR(ISBLANK('IN-CLASS_Lab Part C'!B12)),"Not started",IF(AND(ABS('IN-CLASS_Lab Part C'!B12-(438))<=1e-09),"✓ Checked","Check the result")),"Formula error")
A30: Formatting is already set. Enter your formula, then press Enter. To restore: select cell > Format Cells > Number or Custom.
A31: B7 | B31: Number, 0 decimals, pickups; unrelated formatting example only: stored 7 displays as 7 pickups. This is not a check value. | Format code: 0
A32: B8 | B32: Number, 0 decimals, pickups; unrelated formatting example only: stored 7 displays as 7 pickups. This is not a check value. | Format code: 0
A33: B9 | B33: Percentage, 1 decimal, percent of eligible recorded outcomes; unrelated formatting example only: stored 0.125 displays as 12.5%. This is not a check value. | Format code: 0.0%
A34: B10 | B34: Percentage, 2 decimals, percent of eligible recorded outcomes; unrelated formatting example only: stored 0.125 displays as 12.50%. This is not a check value. | Format code: 0.00%
A35: B11 | B35: Percentage, 2 decimals, percent of eligible recorded outcomes; unrelated formatting example only: stored 0.125 displays as 12.50%. This is not a check value. | Format code: 0.00%
A36: B12 | B36: Number, 0 decimals, completed pickups; unrelated formatting example only: stored 7 displays as 7 completed pickups. This is not a check value. | Format code: 0

Sheet Data
A1: pickup_id | B1: invitation_status | C1: delay_flag | D1: slow_flag | E1: duration | G1: Shared data: cedar_loop_pickups.csv | I1: The respondent rate describes observed outcomes, while invitation bounds show how missing outcomes could change the share. | J1: The interval proves that hiring additional staff will reduce duration. | K1: The planned sample size is automatically the number of invitations needed.
A2: CL000001 | B2: not_invited | G2: Excel: use the table on this sheet. SPSS: use the supplied .sps import. | I2: The respondent rate alone establishes the delay share for every pickup in the frame. | J2: The interval estimates a population mean, so it does not show where 95% of individual durations fall. | K2: A percentage-point margin is a percent change relative to the respondent share.
A3: CL000002 | B3: not_invited | G3: Python/R: read the matching CSV with the types and missing rules below. | I3: The invitation bounds assign known probabilities to the missing outcomes. | J3: The interval contains 95% of recorded individual durations. | K3: A completed-sample precision target does not by itself correct missing-outcome bias.
A4: CL000003 | B4: not_invited | G4: pickup_id | text | Identifier for one recorded pickup; preserve leading zeroes. | units: pickup ID | missing: blank [] | I4: Not-invited pickups should be counted as nonrespondents in the invitation bounds. | J4: The interval is a range for the 2,400-row count rather than for duration. | K4: The observed event share proves permanent staffing changes pickup outcomes.
A5: CL000004 | B5: responded | C5: 1 | D5: 1 | E5: 63.247117 | G5: invitation_status | text | One of responded, nonresponse or not_invited. | units: category | missing: blank []
A6: CL000005 | B6: not_invited | G6: delay_flag | number | Observed delay: 1 for duration greater than 50 minutes, otherwise 0; blank unobserved. | units: binary indicator | missing: blank ['']
A7: CL000006 | B7: not_invited | G7: slow_flag | number | Exact alias of delay_flag for this case: 1 for duration greater than 50 minutes, otherwise 0; blank unobserved. | units: binary indicator | missing: blank ['']
A8: CL000007 | B8: not_invited | G8: duration | number | Recorded pickup duration; blank unobserved. | units: minutes | missing: blank ['']
A9: CL000008 | B9: not_invited
A10: CL000009 | B10: not_invited
A11: CL000010 | B11: not_invited
A12: CL000011 | B12: not_invited
A13: CL000012 | B13: not_invited
A14: CL000013 | B14: not_invited
A15: CL000014 | B15: not_invited
A16: CL000015 | B16: not_invited
A17: CL000016 | B17: not_invited
A18: CL000017 | B18: not_invited
A19: CL000018 | B19: not_invited
A20: CL000019 | B20: not_invited
... A23: CL000022 | B23: not_invited
A24: CL000023 | B24: responded | C24: 1 | D24: 1 | E24: 63.247117
A25: CL000024 | B25: not_invited
A26: CL000025 | B26: not_invited
A27: CL000026 | B27: not_invited
A28: CL000027 | B28: not_invited
A29: CL000028 | B29: not_invited
A30: CL000029 | B30: not_invited
A31: CL000030 | B31: not_invited
A32: CL000031 | B32: not_invited
A33: CL000032 | B33: not_invited
A34: CL000033 | B34: not_invited
A35: CL000034 | B35: not_invited
A36: CL000035 | B36: not_invited
... A39: CL000038 | B39: not_invited
A40: CL000039 | B40: responded | C40: 1 | D40: 1 | E40: 63.247117
A41: CL000040 | B41: responded | C41: 1 | D41: 1 | E41: 63.247117
A42: CL000041 | B42: not_invited
A43: CL000042 | B43: not_invited
A44: CL000043 | B44: not_invited
...
